Workbook

Sheet TopPage
A1: count | B1: 10 | C1: 7 | D1: 5 | E1: 5 | F1: 4 | G1: 3 | H1: 3 | I1: 3 | J1: 3 | K1: 2 | L1: 2 | M1: 1 | N1: 2 | O1: 2 | P1: 2 | Q1: 2 | R1: 1 | S1: 1 | T1: 1 | U1: 1 | V1: 1 | W1: 1 | X1: 1 | Y1: 1 | Z1: 1 | AA1: 1 | AB1: 1 | AC1: 1 | AD1: 1 | AE1: 1 | AF1: 1 | AG1: 1 | AH1: 1 | AI1: 1
A2: group | B2: ALTERS CELL PROLIFERATION AND CELL DEATH | C2: MODULATES NUCLEAR RECEPTOR-MEDIATED EFFECTS | D2: INDUCES OXIDATIVE STRESS | E2: CAUSES INFLAMMATION | F2: INDUCES EPIGENETIC ALTERATIONS | G2: ALTERS SIGNAL TRANSDUCTION | H2: CAUSES MITOCHONDRIAL DYSFUNCTION | I2: IS GENOTOXIC | J2: IS METABOLICALLY ACTIVATED OR REACTIVE | K2: ALTERS CELL-CELL INTERACTIONS AND COMMUNICATION | L2: DISRUPTS CELLULAR CYTOSKELETON | M2: IS IMMUNOSUPPRESSIVE | N2: ALTERS PRODUCTION OF HORMONE | O2: DISRUPTS LIPID AND PROTEIN METABOLISM OR CAUSES DYSLIPIDEMIA | P2: DISRUPTS TRANSPORT FUNCTION | Q2: ALTERS GERM CELL DEVELOPMENT, FUNCTION, OR DEATH | R2: AFFECTS ANTIGEN PROCESSING AND PRESENTATION | S2: ALTERS DNA REPAIR OR CAUSES GENOMIC INSTABILITY | T2: ALTERS EFFECTOR FUNCTION OF SPECIFIC CELL TYPES | U2: ALTERS HEMOSTASIS | V2: ALTERS HORMONE DISTRIBUTION OR CIRCULATING HORMONE LEVELS | W2: ALTERS HORMONE METABOLISM OR CLEARANCE | X2: ALTERS IMMUNE CELL SIGNALING | Y2: ALTERS IMMUNE CELL TRAFFICKING | Z2: BREAKS DOWN IMMUNE TOLERANCE | AA2: ACTIVATES STRESS SIGNALING PATHWAYS | AB2: CAUSES CHOLESTASIS | AC2: CAUSES IMMORTALIZATION | AD2: CAUSES LIVER FIBROSIS | AE2: IMPACTS ENDOTHELIAL AND VASCULAR FUNCTION | AF2: IMPAIRS CARDIAC CONTRACTILITY AND RELAXATION | AG2: IMPAIRS REGULATION OF CARDIAC EXCITABILITY | AH2: MODIFIES AUTONOMIC NERVOUS SYSTEM ACTIVITY | AI2: MODIFIES CELLULAR DIFFERENTIATION
A3: Disease | B3: =SUM(Disease!B3:B709) -> 17 | C3: =SUM(Disease!C3:C709) -> 2 | D3: =SUM(Disease!D3:D709) -> 10 | E3: =SUM(Disease!E3:E709) -> 13 | F3: =SUM(Disease!F3:F709) -> 0 | G3: =SUM(Disease!G3:G709) -> 170 | H3: =SUM(Disease!H3:H709) -> 0 | I3: =SUM(Disease!I3:I709) -> 0 | ... AI3: =SUM(Disease!AI3:AI709) -> 0
A4: Signal Transduction | B4: =SUM('Signal Transduction'!B3:B710) -> 97 | C4: =SUM('Signal Transduction'!C3:C710) -> 70 | D4: =SUM('Signal Transduction'!D3:D710) -> 0 | E4: =SUM('Signal Transduction'!E3:E710) -> 9 | F4: =SUM('Signal Transduction'!F3:F710) -> 0 | G4: =SUM('Signal Transduction'!G3:G710) -> 404 | H4: =SUM('Signal Transduction'!H3:H710) -> 0 | I4: =SUM('Signal Transduction'!I3:I710) -> 0 | ... AI4: =SUM('Signal Transduction'!AI3:AI710) -> 19
A5: Metabolism | B5: =SUM(Metabolism!B3:B711) -> 0 | C5: =SUM(Metabolism!C3:C711) -> 0 | D5: =SUM(Metabolism!D3:D711) -> 20 | E5: =SUM(Metabolism!E3:E711) -> 1 | F5: =SUM(Metabolism!F3:F711) -> 0 | G5: =SUM(Metabolism!G3:G711) -> 0 | H5: =SUM(Metabolism!H3:H711) -> 27 | I5: =SUM(Metabolism!I3:I711) -> 0 | ... AI5: =SUM(Metabolism!AI3:AI711) -> 0
A6: Immune System | B6: =SUM('Immune System'!B3:B712) -> 0 | C6: =SUM('Immune System'!C3:C712) -> 0 | D6: =SUM('Immune System'!D3:D712) -> 0 | E6: =SUM('Immune System'!E3:E712) -> 195 | F6: =SUM('Immune System'!F3:F712) -> 0 | G6: =SUM('Immune System'!G3:G712) -> 0 | H6: =SUM('Immune System'!H3:H712) -> 0 | I6: =SUM('Immune System'!I3:I712) -> 0 | ... AI6: =SUM('Immune System'!AI3:AI712) -> 6
A7: Cell Cycle | B7: =SUM('Cell Cycle'!B3:B713) -> 123 | C7: =SUM('Cell Cycle'!C3:C713) -> 0 | D7: =SUM('Cell Cycle'!D3:D713) -> 0 | E7: =SUM('Cell Cycle'!E3:E713) -> 0 | F7: =SUM('Cell Cycle'!F3:F713) -> 0 | G7: =SUM('Cell Cycle'!G3:G713) -> 0 | H7: =SUM('Cell Cycle'!H3:H713) -> 0 | I7: =SUM('Cell Cycle'!I3:I713) -> 13 | ... AI7: =SUM('Cell Cycle'!AI3:AI713) -> 0
A8: Gene expression (Transcription) | B8: =SUM('Gene expression (Transcription)'!B3:B714) -> 24 | C8: =SUM('Gene expression (Transcription)'!C3:C714) -> 0 | D8: =SUM('Gene expression (Transcription)'!D3:D714) -> 3 | E8: =SUM('Gene expression (Transcription)'!E3:E714) -> 0 | F8: =SUM('Gene expression (Transcription)'!F3:F714) -> 12 | G8: =SUM('Gene expression (Transcription)'!G3:G714) -> 1 | H8: =SUM('Gene expression (Transcription)'!H3:H714) -> 3 | I8: =SUM('Gene expression (Transcription)'!I3:I714) -> 1 | ... AI8: =SUM('Gene expression (Transcription)'!AI3:AI714) -> 7
A9: Metabolism of proteins | B9: =SUM('Metabolism of proteins'!B3:B715) -> 1 | C9: =SUM('Metabolism of proteins'!C3:C715) -> 0 | D9: =SUM('Metabolism of proteins'!D3:D715) -> 1 | E9: =SUM('Metabolism of proteins'!E3:E715) -> 1 | F9: =SUM('Metabolism of proteins'!F3:F715) -> 1 | G9: =SUM('Metabolism of proteins'!G3:G715) -> 0 | H9: =SUM('Metabolism of proteins'!H3:H715) -> 5 | I9: =SUM('Metabolism of proteins'!I3:I715) -> 1 | ... AI9: =SUM('Metabolism of proteins'!AI3:AI715) -> 0
A10: Neuronal System | B10: =SUM('Neuronal System'!B3:B716) -> 0 | C10: =SUM('Neuronal System'!C3:C716) -> 0 | D10: =SUM('Neuronal System'!D3:D716) -> 0 | E10: =SUM('Neuronal System'!E3:E716) -> 0 | F10: =SUM('Neuronal System'!F3:F716) -> 0 | G10: =SUM('Neuronal System'!G3:G716) -> 0 | H10: =SUM('Neuronal System'!H3:H716) -> 0 | I10: =SUM('Neuronal System'!I3:I716) -> 0 | ... AI10: =SUM('Neuronal System'!AI3:AI716) -> 0
A11: Developmental Biology | B11: =SUM('Developmental Biology'!B3:B717) -> 0 | C11: =SUM('Developmental Biology'!C3:C717) -> 0 | D11: =SUM('Developmental Biology'!D3:D717) -> 0 | E11: =SUM('Developmental Biology'!E3:E717) -> 0 | F11: =SUM('Developmental Biology'!F3:F717) -> 0 | G11: =SUM('Developmental Biology'!G3:G717) -> 0 | H11: =SUM('Developmental Biology'!H3:H717) -> 0 | I11: =SUM('Developmental Biology'!I3:I717) -> 0 | ... AI11: =SUM('Developmental Biology'!AI3:AI717) -> 0
A12: Transport of small molecules | B12: =SUM('Transport of small molecules'!B3:B718) -> 0 | C12: =SUM('Transport of small molecules'!C3:C718) -> 0 | D12: =SUM('Transport of small molecules'!D3:D718) -> 0 | E12: =SUM('Transport of small molecules'!E3:E718) -> 0 | F12: =SUM('Transport of small molecules'!F3:F718) -> 0 | G12: =SUM('Transport of small molecules'!G3:G718) -> 0 | H12: =SUM('Transport of small molecules'!H3:H718) -> 3 | I12: =SUM('Transport of small molecules'!I3:I718) -> 0 | ... AI12: =SUM('Transport of small molecules'!AI3:AI718) -> 0
A13: DNA Repair | B13: =SUM('DNA Repair'!B3:B719) -> 0 | C13: =SUM('DNA Repair'!C3:C719) -> 0 | D13: =SUM('DNA Repair'!D3:D719) -> 0 | E13: =SUM('DNA Repair'!E3:E719) -> 0 | F13: =SUM('DNA Repair'!F3:F719) -> 0 | G13: =SUM('DNA Repair'!G3:G719) -> 0 | H13: =SUM('DNA Repair'!H3:H719) -> 0 | I13: =SUM('DNA Repair'!I3:I719) -> 64 | ... AI13: =SUM('DNA Repair'!AI3:AI719) -> 0
A14: Cellular responses to stimuli | B14: =SUM('Cellular responses to stimuli'!B3:B720) -> 6 | C14: =SUM('Cellular responses to stimuli'!C3:C720) -> 0 | D14: =SUM('Cellular responses to stimuli'!D3:D720) -> 17 | E14: =SUM('Cellular responses to stimuli'!E3:E720) -> 11 | F14: =SUM('Cellular responses to stimuli'!F3:F720) -> 0 | G14: =SUM('Cellular responses to stimuli'!G3:G720) -> 0 | H14: =SUM('Cellular responses to stimuli'!H3:H720) -> 3 | I14: =SUM('Cellular responses to stimuli'!I3:I720) -> 1 | ... AI14: =SUM('Cellular responses to stimuli'!AI3:AI720) -> 0
A15: Programmed Cell Death | B15: =SUM('Programmed Cell Death'!B3:B721) -> 41 | C15: =SUM('Programmed Cell Death'!C3:C721) -> 0 | D15: =SUM('Programmed Cell Death'!D3:D721) -> 0 | E15: =SUM('Programmed Cell Death'!E3:E721) -> 1 | F15: =SUM('Programmed Cell Death'!F3:F721) -> 0 | G15: =SUM('Programmed Cell Death'!G3:G721) -> 0 | H15: =SUM('Programmed Cell Death'!H3:H721) -> 0 | I15: =SUM('Programmed Cell Death'!I3:I721) -> 0 | ... AI15: =SUM('Programmed Cell Death'!AI3:AI721) -> 0
A16: Hemostasis | B16: =SUM(Hemostasis!B3:B722) -> 0 | C16: =SUM(Hemostasis!C3:C722) -> 0 | D16: =SUM(Hemostasis!D3:D722) -> 0 | E16: =SUM(Hemostasis!E3:E722) -> 0 | F16: =SUM(Hemostasis!F3:F722) -> 0 | G16: =SUM(Hemostasis!G3:G722) -> 0 | H16: =SUM(Hemostasis!H3:H722) -> 0 | I16: =SUM(Hemostasis!I3:I722) -> 0 | ... AI16: =SUM(Hemostasis!AI3:AI722) -> 0
A17: Vesicle-mediated transport | B17: =SUM('Vesicle-mediated transport'!B3:B723) -> 0 | C17: =SUM('Vesicle-mediated transport'!C3:C723) -> 6 | D17: =SUM('Vesicle-mediated transport'!D3:D723) -> 0 | E17: =SUM('Vesicle-mediated transport'!E3:E723) -> 0 | F17: =SUM('Vesicle-mediated transport'!F3:F723) -> 0 | G17: =SUM('Vesicle-mediated transport'!G3:G723) -> 0 | H17: =SUM('Vesicle-mediated transport'!H3:H723) -> 0 | I17: =SUM('Vesicle-mediated transport'!I3:I723) -> 0 | ... AI17: =SUM('Vesicle-mediated transport'!AI3:AI723) -> 0
A18: Metabolism of RNA | B18: =SUM('Metabolism of RNA'!B3:B724) -> 0 | C18: =SUM('Metabolism of RNA'!C3:C724) -> 0 | D18: =SUM('Metabolism of RNA'!D3:D724) -> 0 | E18: =SUM('Metabolism of RNA'!E3:E724) -> 0 | F18: =SUM('Metabolism of RNA'!F3:F724) -> 2 | G18: =SUM('Metabolism of RNA'!G3:G724) -> 0 | H18: =SUM('Metabolism of RNA'!H3:H724) -> 6 | I18: =SUM('Metabolism of RNA'!I3:I724) -> 0 | ... AI18: =SUM('Metabolism of RNA'!AI3:AI724) -> 0
A19: DNA Replication | B19: =SUM('DNA Replication'!B3:B725) -> 18 | C19: =SUM('DNA Replication'!C3:C725) -> 0 | D19: =SUM('DNA Replication'!D3:D725) -> 0 | E19: =SUM('DNA Replication'!E3:E725) -> 0 | F19: =SUM('DNA Replication'!F3:F725) -> 0 | G19: =SUM('DNA Replication'!G3:G725) -> 0 | H19: =SUM('DNA Replication'!H3:H725) -> 0 | I19: =SUM('DNA Replication'!I3:I725) -> 0 | ... AI19: =SUM('DNA Replication'!AI3:AI725) -> 0
A20: Sensory Perception | B20: =SUM('Sensory Perception'!B3:B726) -> 0 | C20: =SUM('Sensory Perception'!C3:C726) -> 0 | D20: =SUM('Sensory Perception'!D3:D726) -> 0 | E20: =SUM('Sensory Perception'!E3:E726) -> 0 | F20: =SUM('Sensory Perception'!F3:F726) -> 0 | G20: =SUM('Sensory Perception'!G3:G726) -> 0 | H20: =SUM('Sensory Perception'!H3:H726) -> 0 | I20: =SUM('Sensory Perception'!I3:I726) -> 0 | ... AI20: =SUM('Sensory Perception'!AI3:AI726) -> 0
A21: Extracellular matrix organization | B21: =SUM('Extracellular matrix organizati'!B3:B727) -> 0 | C21: =SUM('Extracellular matrix organizati'!C3:C727) -> 0 | D21: =SUM('Extracellular matrix organizati'!D3:D727) -> 0 | E21: =SUM('Extracellular matrix organizati'!E3:E727) -> 0 | F21: =SUM('Extracellular matrix organizati'!F3:F727) -> 0 | G21: =SUM('Extracellular matrix organizati'!G3:G727) -> 0 | H21: =SUM('Extracellular matrix organizati'!H3:H727) -> 0 | I21: =SUM('Extracellular matrix organizati'!I3:I727) -> 0 | ... AI21: =SUM('Extracellular matrix organizati'!AI3:AI727) -> 0
A22: Cell-Cell communication | B22: =SUM('Cell-Cell communication'!B3:B728) -> 0 | C22: =SUM('Cell-Cell communication'!C3:C728) -> 0 | D22: =SUM('Cell-Cell communication'!D3:D728) -> 0 | E22: =SUM('Cell-Cell communication'!E3:E728) -> 0 | F22: =SUM('Cell-Cell communication'!F3:F728) -> 0 | G22: =SUM('Cell-Cell communication'!G3:G728) -> 0 | H22: =SUM('Cell-Cell communication'!H3:H728) -> 0 | I22: =SUM('Cell-Cell communication'!I3:I728) -> 0 | ... AI22: =SUM('Cell-Cell communication'!AI3:AI728) -> 0
A23: Organelle biogenesis and maintenance | B23: =SUM('Organelle biogenesis and mainte'!B3:B729) -> 0 | C23: =SUM('Organelle biogenesis and mainte'!C3:C729) -> 0 | D23: =SUM('Organelle biogenesis and mainte'!D3:D729) -> 0 | E23: =SUM('Organelle biogenesis and mainte'!E3:E729) -> 0 | F23: =SUM('Organelle biogenesis and mainte'!F3:F729) -> 0 | G23: =SUM('Organelle biogenesis and mainte'!G3:G729) -> 0 | H23: =SUM('Organelle biogenesis and mainte'!H3:H729) -> 5 | I23: =SUM('Organelle biogenesis and mainte'!I3:I729) -> 0 | ... AI23: =SUM('Organelle biogenesis and mainte'!AI3:AI729) -> 0
A24: Autophagy | B24: =SUM(Autophagy!B3:B730) -> 11 | C24: =SUM(Autophagy!C3:C730) -> 0 | D24: =SUM(Autophagy!D3:D730) -> 1 | E24: =SUM(Autophagy!E3:E730) -> 0 | F24: =SUM(Autophagy!F3:F730) -> 0 | G24: =SUM(Autophagy!G3:G730) -> 0 | H24: =SUM(Autophagy!H3:H730) -> 3 | I24: =SUM(Autophagy!I3:I730) -> 0 | ... AI24: =SUM(Autophagy!AI3:AI730) -> 0
A25: Drug ADME | B25: =SUM('Drug ADME'!B3:B720) -> 0 | C25: =SUM('Drug ADME'!C3:C720) -> 0 | D25: =SUM('Drug ADME'!D3:D720) -> 0 | E25: =SUM('Drug ADME'!E3:E720) -> 0 | F25: =SUM('Drug ADME'!F3:F720) -> 0 | G25: =SUM('Drug ADME'!G3:G720) -> 0 | H25: =SUM('Drug ADME'!H3:H720) -> 0 | I25: =SUM('Drug ADME'!I3:I720) -> 0 | ... AI25: =SUM('Drug ADME'!AI3:AI720) -> 0
A26: Muscle contraction | B26: =SUM('Muscle contraction'!B3:B721) -> 0 | C26: =SUM('Muscle contraction'!C3:C721) -> 0 | D26: =SUM('Muscle contraction'!D3:D721) -> 0 | E26: =SUM('Muscle contraction'!E3:E721) -> 0 | F26: =SUM('Muscle contraction'!F3:F721) -> 0 | G26: =SUM('Muscle contraction'!G3:G721) -> 0 | H26: =SUM('Muscle contraction'!H3:H721) -> 0 | I26: =SUM('Muscle contraction'!I3:I721) -> 0 | ... AI26: =SUM('Muscle contraction'!AI3:AI721) -> 0
A27: Reproduction | B27: =SUM(Reproduction!B3:B721) -> 0 | C27: =SUM(Reproduction!C3:C721) -> 0 | D27: =SUM(Reproduction!D3:D721) -> 0 | E27: =SUM(Reproduction!E3:E721) -> 0 | F27: =SUM(Reproduction!F3:F721) -> 0 | G27: =SUM(Reproduction!G3:G721) -> 0 | H27: =SUM(Reproduction!H3:H721) -> 0 | I27: =SUM(Reproduction!I3:I721) -> 0 | ... AI27: =SUM(Reproduction!AI3:AI721) -> 0
A28: Chromatin organization | B28: =SUM('Chromatin organization'!B3:B716) -> 0 | C28: =SUM('Chromatin organization'!C3:C716) -> 0 | D28: =SUM('Chromatin organization'!D3:D716) -> 0 | E28: =SUM('Chromatin organization'!E3:E716) -> 0 | F28: =SUM('Chromatin organization'!F3:F716) -> 6 | G28: =SUM('Chromatin organization'!G3:G716) -> 0 | H28: =SUM('Chromatin organization'!H3:H716) -> 0 | I28: =SUM('Chromatin organization'!I3:I716) -> 0 | ... AI28: =SUM('Chromatin organization'!AI3:AI716) -> 0
A29: Digestion and absorption | B29: =SUM('Digestion and absorption'!B3:B716) -> 0 | C29: =SUM('Digestion and absorption'!C3:C716) -> 0 | D29: =SUM('Digestion and absorption'!D3:D716) -> 0 | E29: =SUM('Digestion and absorption'!E3:E716) -> 0 | F29: =SUM('Digestion and absorption'!F3:F716) -> 0 | G29: =SUM('Digestion and absorption'!G3:G716) -> 0 | H29: =SUM('Digestion and absorption'!H3:H716) -> 0 | I29: =SUM('Digestion and absorption'!I3:I716) -> 0 | ... AI29: =SUM('Digestion and absorption'!AI3:AI716) -> 0
A30: Protein localization | B30: =SUM('Protein localization'!B3:B715) -> 0 | C30: =SUM('Protein localization'!C3:C715) -> 0 | D30: =SUM('Protein localization'!D3:D715) -> 0 | E30: =SUM('Protein localization'!E3:E715) -> 0 | F30: =SUM('Protein localization'!F3:F715) -> 0 | G30: =SUM('Protein localization'!G3:G715) -> 0 | H30: =SUM('Protein localization'!H3:H715) -> 1 | I30: =SUM('Protein localization'!I3:I715) -> 0 | ... AI30: =SUM('Protein localization'!AI3:AI715) -> 0
A31: Circadian Clock | B31: =SUM('Circadian Clock'!B3:B713) -> 0 | C31: =SUM('Circadian Clock'!C3:C713) -> 0 | D31: =SUM('Circadian Clock'!D3:D713) -> 0 | E31: =SUM('Circadian Clock'!E3:E713) -> 0 | F31: =SUM('Circadian Clock'!F3:F713) -> 0 | G31: =SUM('Circadian Clock'!G3:G713) -> 0 | H31: =SUM('Circadian Clock'!H3:H713) -> 0 | I31: =SUM('Circadian Clock'!I3:I713) -> 0 | ... AI31: =SUM('Circadian Clock'!AI3:AI713) -> 0
B32: =SUM(B3:B31) -> 338 | C32: =SUM(C3:C31) -> 78 | D32: =SUM(D3:D31) -> 52 | E32: =SUM(E3:E31) -> 231 | F32: =SUM(F3:F31) -> 21 | G32: =SUM(G3:G31) -> 575 | H32: =SUM(H3:H31) -> 56 | I32: =SUM(I3:I31) -> 80 | ... AI32: =SUM(AI3:AI31) -> 32

Sheet Disease
A1: Back to main page
A2: group | B2: ALTERS CELL PROLIFERATION AND CELL DEATH | C2: MODULATES NUCLEAR RECEPTOR-MEDIATED EFFECTS | D2: INDUCES OXIDATIVE STRESS | E2: CAUSES INFLAMMATION | F2: INDUCES EPIGENETIC ALTERATIONS | G2: ALTERS SIGNAL TRANSDUCTION | H2: CAUSES MITOCHONDRIAL DYSFUNCTION | I2: IS GENOTOXIC | J2: IS METABOLICALLY ACTIVATED OR REACTIVE | K2: ALTERS CELL-CELL INTERACTIONS AND COMMUNICATION | L2: DISRUPTS CELLULAR CYTOSKELETON | M2: IS IMMUNOSUPPRESSIVE | N2: ALTERS PRODUCTION OF HORMONE | O2: DISRUPTS LIPID AND PROTEIN METABOLISM OR CAUSES DYSLIPIDEMIA | P2: DISRUPTS TRANSPORT FUNCTION | Q2: ALTERS GERM CELL DEVELOPMENT, FUNCTION, OR DEATH | R2: AFFECTS ANTIGEN PROCESSING AND PRESENTATION | S2: ALTERS DNA REPAIR OR CAUSES GENOMIC INSTABILITY | T2: ALTERS EFFECTOR FUNCTION OF SPECIFIC CELL TYPES | U2: ALTERS HEMOSTASIS | V2: ALTERS HORMONE DISTRIBUTION OR CIRCULATING HORMONE LEVELS | W2: ALTERS HORMONE METABOLISM OR CLEARANCE | X2: ALTERS IMMUNE CELL SIGNALING | Y2: ALTERS IMMUNE CELL TRAFFICKING | Z2: BREAKS DOWN IMMUNE TOLERANCE | AA2: ACTIVATES STRESS SIGNALING PATHWAYS | AB2: CAUSES CHOLESTASIS | AC2: CAUSES IMMORTALIZATION | AD2: CAUSES LIVER FIBROSIS | AE2: IMPACTS ENDOTHELIAL AND VASCULAR FUNCTION | AF2: IMPAIRS CARDIAC CONTRACTILITY AND RELAXATION | AG2: IMPAIRS REGULATION OF CARDIAC EXCITABILITY | AH2: MODIFIES AUTONOMIC NERVOUS SYSTEM ACTIVITY | AI2: MODIFIES CELLULAR DIFFERENTIATION
A3: Diseases of Immune System | B3: 0 | C3: 0 | D3: 0 | E3: 1 | F3: 0 | G3: 0 | H3: 0 | I3: 0 | J3: 0 | K3: 0 | L3: 0 | M3: 0 | N3: 0 | O3: 0 | P3: 0 | Q3: 0 | R3: 0 | S3: 0 | T3: 0 | U3: 0 | V3: 0 | W3: 0 | X3: 1 | Y3: 0 | Z3: 0 | AA3: 0 | AB3: 0 | AC3: 0 | AD3: 0 | AE3: 0 | AF3: 0 | AG3: 0 | AH3: 0 | AI3: 0
A4: Disorders of transmembrane transporters | B4: 0 | C4: 0 | D4: 0 | E4: 0 | F4: 0 | G4: 0 | H4: 0 | I4: 0 | J4: 0 | K4: 0 | L4: 0 | M4: 0 | N4: 0 | O4: 0 | P4: 1 | Q4: 0 | R4: 0 | S4: 0 | T4: 0 | U4: 0 | V4: 0 | W4: 0 | X4: 0 | Y4: 0 | Z4: 0 | AA4: 0 | AB4: 0 | AC4: 0 | AD4: 0 | AE4: 0 | AF4: 0 | AG4: 0 | AH4: 0 | AI4: 0
A5: Diseases of signal transduction by growth factor receptors and second messengers | B5: 0 | C5: 0 | D5: 0 | E5: 0 | F5: 0 | G5: 1 | H5: 0 | I5: 0 | J5: 0 | K5: 0 | L5: 0 | M5: 0 | N5: 0 | O5: 0 | P5: 0 | Q5: 0 | R5: 0 | S5: 0 | T5: 0 | U5: 0 | V5: 0 | W5: 0 | X5: 0 | Y5: 0 | Z5: 0 | AA5: 0 | AB5: 0 | AC5: 0 | AD5: 0 | AE5: 0 | AF5: 0 | AG5: 0 | AH5: 0 | AI5: 0
A6: Infectious disease | B6: 0 | C6: 0 | D6: 0 | E6: 0 | F6: 0 | G6: 0 | H6: 0 | I6: 0 | J6: 0 | K6: 0 | L6: 0 | M6: 0 | N6: 0 | O6: 0 | P6: 0 | Q6: 0 | R6: 0 | S6: 0 | T6: 0 | U6: 0 | V6: 0 | W6: 0 | X6: 0 | Y6: 0 | Z6: 0 | AA6: 0 | AB6: 0 | AC6: 0 | AD6: 0 | AE6: 0 | AF6: 0 | AG6: 0 | AH6: 0 | AI6: 0
A7: Diseases of metabolism | B7: 0 | C7: 0 | D7: 0 | E7: 0 | F7: 0 | G7: 0 | H7: 0 | I7: 0 | J7: 0 | K7: 0 | L7: 0 | M7: 0 | N7: 0 | O7: 0 | P7: 0 | Q7: 0 | R7: 0 | S7: 0 | T7: 0 | U7: 0 | V7: 0 | W7: 0 | X7: 0 | Y7: 0 | Z7: 0 | AA7: 0 | AB7: 0 | AC7: 0 | AD7: 0 | AE7: 0 | AF7: 0 | AG7: 0 | AH7: 0 | AI7: 0
A8: Diseases of programmed cell death | B8: 1 | C8: 0 | D8: 0 | E8: 0 | F8: 0 | G8: 0 | H8: 0 | I8: 0 | J8: 0 | K8: 0 | L8: 0 | M8: 0 | N8: 0 | O8: 0 | P8: 0 | Q8: 0 | R8: 0 | S8: 0 | T8: 0 | U8: 0 | V8: 0 | W8: 0 | X8: 0 | Y8: 0 | Z8: 0 | AA8: 0 | AB8: 0 | AC8: 0 | AD8: 0 | AE8: 0 | AF8: 0 | AG8: 0 | AH8: 0 | AI8: 0
A9: Diseases of hemostasis | B9: 0 | C9: 0 | D9: 0 | E9: 0 | F9: 0 | G9: 0 | H9: 0 | I9: 0 | J9: 0 | K9: 0 | L9: 0 | M9: 0 | N9: 0 | O9: 0 | P9: 0 | Q9: 0 | R9: 0 | S9: 0 | T9: 0 | U9: 1 | V9: 0 | W9: 0 | X9: 0 | Y9: 0 | Z9: 0 | AA9: 0 | AB9: 0 | AC9: 0 | AD9: 0 | AE9: 0 | AF9: 0 | AG9: 0 | AH9: 0 | AI9: 0
A10: Diseases of mitotic cell cycle | B10: 1 | C10: 0 | D10: 0 | E10: 0 | F10: 0 | G10: 0 | H10: 0 | I10: 0 | J10: 0 | K10: 0 | L10: 0 | M10: 0 | N10: 0 | O10: 0 | P10: 0 | Q10: 0 | R10: 0 | S10: 0 | T10: 0 | U10: 0 | V10: 0 | W10: 0 | X10: 0 | Y10: 0 | Z10: 0 | AA10: 0 | AB10: 0 | AC10: 0 | AD10: 0 | AE10: 0 | AF10: 0 | AG10: 0 | AH10: 0 | AI10: 0
A11: Diseases of cellular response to stress | B11: 0 | C11: 0 | D11: 0 | E11: 0 | F11: 0 | G11: 1 | H11: 0 | I11: 0 | J11: 0 | K11: 0 | L11: 0 | M11: 0 | N11: 0 | O11: 0 | P11: 0 | Q11: 0 | R11: 0 | S11: 0 | T11: 0 | U11: 0 | V11: 0 | W11: 0 | X11: 0 | Y11: 0 | Z11: 0 | AA11: 0 | AB11: 0 | AC11: 0 | AD11: 0 | AE11: 0 | AF11: 0 | AG11: 0 | AH11: 0 | AI11: 0
A12: Diseases of DNA repair | B12: 0 | C12: 0 | D12: 0 | E12: 0 | F12: 0 | G12: 0 | H12: 0 | I12: 0 | J12: 0 | K12: 0 | L12: 0 | M12: 0 | N12: 0 | O12: 0 | P12: 0 | Q12: 0 | R12: 0 | S12: 1 | T12: 0 | U12: 0 | V12: 0 | W12: 0 | X12: 0 | Y12: 0 | Z12: 0 | AA12: 0 | AB12: 0 | AC12: 0 | AD12: 0 | AE12: 0 | AF12: 0 | AG12: 0 | AH12: 0 | AI12: 0
A13: Diseases of the neuronal system | B13: 0 | C13: 0 | D13: 0 | E13: 0 | F13: 0 | G13: 0 | H13: 0 | I13: 0 | J13: 0 | K13: 0 | L13: 0 | M13: 0 | N13: 0 | O13: 0 | P13: 0 | Q13: 0 | R13: 0 | S13: 0 | T13: 0 | U13: 0 | V13: 0 | W13: 0 | X13: 0 | Y13: 0 | Z13: 0 | AA13: 0 | AB13: 0 | AC13: 0 | AD13: 0 | AE13: 0 | AF13: 0 | AG13: 0 | AH13: 0 | AI13: 0
A14: Disorders of Developmental Biology | B14: 0 | C14: 0 | D14: 0 | E14: 0 | F14: 0 | G14: 0 | H14: 0 | I14: 0 | J14: 0 | K14: 0 | L14: 0 | M14: 0 | N14: 0 | O14: 0 | P14: 0 | Q14: 0 | R14: 0 | S14: 0 | T14: 0 | U14: 0 | V14: 0 | W14: 0 | X14: 0 | Y14: 0 | Z14: 0 | AA14: 0 | AB14: 0 | AC14: 0 | AD14: 0 | AE14: 0 | AF14: 0 | AG14: 0 | AH14: 0 | AI14: 0
... A626: Microbial modulation of RIPK1-mediated regulated necrosis | B626: 1 | C626: 0 | D626: 0 | E626: 0 | F626: 0 | G626: 0 | H626: 0 | I626: 0 | J626: 0 | K626: 0 | L626: 0 | M626: 0 | N626: 0 | O626: 0 | P626: 0 | Q626: 0 | R626: 0 | S626: 0 | T626: 0 | U626: 0 | V626: 0 | W626: 0 | X626: 0 | Y626: 0 | Z626: 0 | AA626: 0 | AB626: 0 | AC626: 0 | AD626: 0 | AE626: 0 | AF626: 0 | AG626: 0 | AH626: 0 | AI626: 0
A627: Neurodegenerative Diseases | C627: 0 | D627: 0 | E627: 0 | F627: 0 | G627: 0 | H627: 0 | I627: 0 | J627: 0 | K627: 0 | L627: 0 | M627: 0 | N627: 0 | O627: 0 | P627: 0 | Q627: 0 | R627: 0 | S627: 0 | T627: 0 | U627: 0 | V627: 0 | W627: 0 | X627: 0 | Y627: 0 | Z627: 0 | AA627: 0 | AB627: 0 | AC627: 0 | AD627: 0 | AE627: 0 | AF627: 0 | AG627: 0 | AH627: 0 | AI627: 0
A628: Defective Intrinsic Pathway for Apoptosis Due to p14ARF Loss of Function | B628: 1 | C628: 0 | D628: 0 | E628: 0 | F628: 0 | G628: 0 | H628: 0 | I628: 0 | J628: 0 | K628: 0 | L628: 0 | M628: 0 | N628: 0 | O628: 0 | P628: 0 | Q628: 0 | R628: 0 | S628: 0 | T628: 0 | U628: 0 | V628: 0 | W628: 0 | X628: 0 | Y628: 0 | Z628: 0 | AA628: 0 | AB628: 0 | AC628: 0 | AD628: 0 | AE628: 0 | AF628: 0 | AG628: 0 | AH628: 0 | AI628: 0
A629: Loss of Function of TP53 in Cancer | B629: 1 | C629: 0 | D629: 0 | E629: 0 | F629: 0 | G629: 0 | H629: 0 | I629: 0 | J629: 0 | K629: 0 | L629: 0 | M629: 0 | N629: 0 | O629: 0 | P629: 0 | Q629: 0 | R629: 0 | S629: 0 | T629: 0 | U629: 0 | V629: 0 | W629: 0 | X629: 0 | Y629: 0 | Z629: 0 | AA629: 0 | AB629: 0 | AC629: 0 | AD629: 0 | AE629: 0 | AF629: 0 | AG629: 0 | AH629: 0 | AI629: 0
A630: Deregulated CDK5 triggers multiple neurodegenerative pathways in Alzheimer's disease models | B630: 0 | C630: 0 | D630: 0 | E630: 0 | F630: 0 | G630: 0 | H630: 0 | I630: 0 | J630: 0 | K630: 0 | L630: 0 | M630: 0 | N630: 0 | O630: 0 | P630: 0 | Q630: 0 | R630: 0 | S630: 0 | T630: 0 | U630: 0 | V630: 0 | W630: 0 | X630: 0 | Y630: 0 | Z630: 0 | AA630: 0 | AB630: 0 | AC630: 0 | AD630: 0 | AE630: 0 | AF630: 0 | AG630: 0 | AH630: 0 | AI630: 0
A631: Loss of function of TP53 in cancer due to loss of tetramerization ability | B631: 1 | C631: 0 | D631: 0 | E631: 0 | F631: 0 | G631: 0 | H631: 0 | I631: 0 | J631: 0 | K631: 0 | L631: 0 | M631: 0 | N631: 0 | O631: 0 | P631: 0 | Q631: 0 | R631: 0 | S631: 0 | T631: 0 | U631: 0 | V631: 0 | W631: 0 | X631: 0 | Y631: 0 | Z631: 0 | AA631: 0 | AB631: 0 | AC631: 0 | AD631: 0 | AE631: 0 | AF631: 0 | AG631: 0 | AH631: 0 | AI631: 0
A632: Defects of contact activation system (CAS) and kallikrein/kinin system (KKS) | B632: 0 | C632: 0 | D632: 0 | E632: 0 | F632: 0 | G632: 0 | H632: 0 | I632: 0 | J632: 0 | K632: 0 | L632: 0 | M632: 0 | N632: 0 | O632: 0 | P632: 0 | Q632: 0 | R632: 0 | S632: 0 | T632: 0 | U632: 1 | V632: 0 | W632: 0 | X632: 0 | Y632: 0 | Z632: 0 | AA632: 0 | AB632: 0 | AC632: 0 | AD632: 0 | AE632: 0 | AF632: 0 | AG632: 0 | AH632: 0 | AI632: 0
A633: Defective factor XII causes hereditary angioedema | B633: 0 | C633: 0 | D633: 0 | E633: 0 | F633: 0 | G633: 0 | H633: 0 | I633: 0 | J633: 0 | K633: 0 | L633: 0 | M633: 0 | N633: 0 | O633: 0 | P633: 0 | Q633: 0 | R633: 0 | S633: 0 | T633: 0 | U633: 1 | V633: 0 | W633: 0 | X633: 0 | Y633: 0 | Z633: 0 | AA633: 0 | AB633: 0 | AC633: 0 | AD633: 0 | AE633: 0 | AF633: 0 | AG633: 0 | AH633: 0 | AI633: 0
A634: Defective SERPING1 causes hereditary angioedema | B634: 0 | C634: 0 | D634: 0 | E634: 0 | F634: 0 | G634: 0 | H634: 0 | I634: 0 | J634: 0 | K634: 0 | L634: 0 | M634: 0 | N634: 0 | O634: 0 | P634: 0 | Q634: 0 | R634: 0 | S634: 0 | T634: 0 | U634: 0 | V634: 0 | W634: 0 | X634: 0 | Y634: 0 | Z634: 0 | AA634: 0 | AB634: 0 | AC634: 0 | AD634: 0 | AE634: 0 | AF634: 0 | AG634: 0 | AH634: 0 | AI634: 0
A635: Defective factor VIII causes hemophilia A | B635: 0 | C635: 0 | D635: 0 | E635: 0 | F635: 0 | G635: 0 | H635: 0 | I635: 0 | J635: 0 | K635: 0 | L635: 0 | M635: 0 | N635: 0 | O635: 0 | P635: 0 | Q635: 0 | R635: 0 | S635: 0 | T635: 0 | U635: 1 | V635: 0 | W635: 0 | X635: 0 | Y635: 0 | Z635: 0 | AA635: 0 | AB635: 0 | AC635: 0 | AD635: 0 | AE635: 0 | AF635: 0 | AG635: 0 | AH635: 0 | AI635: 0
A636: Defective factor IX causes hemophilia B | B636: 0 | C636: 0 | D636: 0 | E636: 0 | F636: 0 | G636: 0 | H636: 0 | I636: 0 | J636: 0 | K636: 0 | L636: 0 | M636: 0 | N636: 0 | O636: 0 | P636: 0 | Q636: 0 | R636: 0 | S636: 0 | T636: 0 | U636: 1 | V636: 0 | W636: 0 | X636: 0 | Y636: 0 | Z636: 0 | AA636: 0 | AB636: 0 | AC636: 0 | AD636: 0 | AE636: 0 | AF636: 0 | AG636: 0 | AH636: 0 | AI636: 0
A637: Defective factor IX causes thrombophilia | B637: 0 | C637: 0 | D637: 0 | E637: 0 | F637: 0 | G637: 0 | H637: 0 | I637: 0 | J637: 0 | K637: 0 | L637: 0 | M637: 0 | N637: 0 | O637: 0 | P637: 0 | Q637: 0 | R637: 0 | S637: 0 | T637: 0 | U637: 1 | V637: 0 | W637: 0 | X637: 0 | Y637: 0 | Z637: 0 | AA637: 0 | AB637: 0 | AC637: 0 | AD637: 0 | AE637: 0 | AF637: 0 | AG637: 0 | AH637: 0 | AI637: 0
A638: Defective F8 accelerates dissociation of the A2 domain | B638: 0 | C638: 0 | D638: 0 | E638: 0 | F638: 0 | G638: 0 | H638: 0 | I638: 0 | J638: 0 | K638: 0 | L638: 0 | M638: 0 | N638: 0 | O638: 0 | P638: 0 | Q638: 0 | R638: 0 | S638: 0 | T638: 0 | U638: 1 | V638: 0 | W638: 0 | X638: 0 | Y638: 0 | Z638: 0 | AA638: 0 | AB638: 0 | AC638: 0 | AD638: 0 | AE638: 0 | AF638: 0 | AG638: 0 | AH638: 0 | AI638: 0
A639: Defective F8 cleavage by thrombin | B639: 0 | C639: 0 | D639: 0 | E639: 0 | F639: 0 | G639: 0 | H639: 0 | I639: 0 | J639: 0 | K639: 0 | L639: 0 | M639: 0 | N639: 0 | O639: 0 | P639: 0 | Q639: 0 | R639: 0 | S639: 0 | T639: 0 | U639: 1 | V639: 0 | W639: 0 | X639: 0 | Y639: 0 | Z639: 0 | AA639: 0 | AB639: 0 | AC639: 0 | AD639: 0 | AE639: 0 | AF639: 0 | AG639: 0 | AH639: 0 | AI639: 0
... A709: Loss of MECP2 binding ability to 5mC-DNA | B709: 0 | C709: 0 | D709: 0 | E709: 0 | F709: 0 | G709: 0 | H709: 0 | I709: 0 | J709: 0 | K709: 0 | L709: 0 | M709: 0 | N709: 0 | O709: 0 | P709: 0 | Q709: 0 | R709: 0 | S709: 0 | T709: 0 | U709: 0 | V709: 0 | W709: 0 | X709: 0 | Y709: 0 | Z709: 0 | AA709: 0 | AB709: 0 | AC709: 0 | AD709: 0 | AE709: 0 | AF709: 0 | AG709: 0 | AH709: 0 | AI709: 0

Sheet Signal Transduction
A1: Back to main page
A2: group | B2: ALTERS CELL PROLIFERATION AND CELL DEATH | C2: MODULATES NUCLEAR RECEPTOR-MEDIATED EFFECTS | D2: INDUCES OXIDATIVE STRESS | E2: CAUSES INFLAMMATION | F2: INDUCES EPIGENETIC ALTERATIONS | G2: ALTERS SIGNAL TRANSDUCTION | H2: CAUSES MITOCHONDRIAL DYSFUNCTION | I2: IS GENOTOXIC | J2: IS METABOLICALLY ACTIVATED OR REACTIVE | K2: ALTERS CELL-CELL INTERACTIONS AND COMMUNICATION | L2: DISRUPTS CELLULAR CYTOSKELETON | M2: IS IMMUNOSUPPRESSIVE | N2: ALTERS PRODUCTION OF HORMONE | O2: DISRUPTS LIPID AND PROTEIN METABOLISM OR CAUSES DYSLIPIDEMIA | P2: DISRUPTS TRANSPORT FUNCTION | Q2: ALTERS GERM CELL DEVELOPMENT, FUNCTION, OR DEATH | R2: AFFECTS ANTIGEN PROCESSING AND PRESENTATION | S2: ALTERS DNA REPAIR OR CAUSES GENOMIC INSTABILITY | T2: ALTERS EFFECTOR FUNCTION OF SPECIFIC CELL TYPES | U2: ALTERS HEMOSTASIS | V2: ALTERS HORMONE DISTRIBUTION OR CIRCULATING HORMONE LEVELS | W2: ALTERS HORMONE METABOLISM OR CLEARANCE | X2: ALTERS IMMUNE CELL SIGNALING | Y2: ALTERS IMMUNE CELL TRAFFICKING | Z2: BREAKS DOWN IMMUNE TOLERANCE | AA2: ACTIVATES STRESS SIGNALING PATHWAYS | AB2: CAUSES CHOLESTASIS | AC2: CAUSES IMMORTALIZATION | AD2: CAUSES LIVER FIBROSIS | AE2: IMPACTS ENDOTHELIAL AND VASCULAR FUNCTION | AF2: IMPAIRS CARDIAC CONTRACTILITY AND RELAXATION | AG2: IMPAIRS REGULATION OF CARDIAC EXCITABILITY | AH2: MODIFIES AUTONOMIC NERVOUS SYSTEM ACTIVITY | AI2: MODIFIES CELLULAR DIFFERENTIATION
A3: Signaling by NOTCH | B3: 1 | C3: 0 | D3: 0 | E3: 0 | F3: 0 | G3: 1 | H3: 0 | I3: 0 | J3: 0 | K3: 1 | L3: 0 | M3: 0 | N3: 0 | O3: 0 | P3: 0 | Q3: 0 | R3: 0 | S3: 0 | T3: 0 | U3: 0 | V3: 0 | W3: 0 | X3: 0 | Y3: 0 | Z3: 0 | AA3: 0 | AB3: 0 | AC3: 0 | AD3: 0 | AE3: 0 | AF3: 0 | AG3: 0 | AH3: 0 | AI3: 1
A4: MTOR signalling | B4: 1 | C4: 0 | D4: 0 | E4: 0 | F4: 0 | G4: 1 | H4: 0 | I4: 0 | J4: 0 | K4: 0 | L4: 0 | M4: 0 | N4: 0 | O4: 0 | P4: 0 | Q4: 0 | R4: 0 | S4: 0 | T4: 0 | U4: 0 | V4: 0 | W4: 0 | X4: 0 | Y4: 0 | Z4: 0 | AA4: 0 | AB4: 0 | AC4: 0 | AD4: 0 | AE4: 0 | AF4: 0 | AG4: 0 | AH4: 0 | AI4: 0
A5: Signaling by WNT | B5: 1 | C5: 0 | D5: 0 | E5: 0 | F5: 0 | G5: 1 | H5: 0 | I5: 0 | J5: 0 | K5: 0 | L5: 0 | M5: 0 | N5: 0 | O5: 0 | P5: 0 | Q5: 0 | R5: 0 | S5: 0 | T5: 0 | U5: 0 | V5: 0 | W5: 0 | X5: 0 | Y5: 0 | Z5: 0 | AA5: 0 | AB5: 0 | AC5: 0 | AD5: 0 | AE5: 0 | AF5: 0 | AG5: 0 | AH5: 0 | AI5: 0
A6: Signaling by Hippo | B6: 1 | C6: 0 | D6: 0 | E6: 0 | F6: 0 | G6: 1 | H6: 0 | I6: 0 | J6: 0 | K6: 0 | L6: 0 | M6: 0 | N6: 0 | O6: 0 | P6: 0 | Q6: 0 | R6: 0 | S6: 0 | T6: 0 | U6: 0 | V6: 0 | W6: 0 | X6: 0 | Y6: 0 | Z6: 0 | AA6: 0 | AB6: 0 | AC6: 0 | AD6: 0 | AE6: 0 | AF6: 0 | AG6: 0 | AH6: 0 | AI6: 0
A7: Signaling by Leptin | B7: 0 | C7: 0 | D7: 0 | E7: 0 | F7: 0 | G7: 1 | H7: 0 | I7: 0 | J7: 0 | K7: 0 | L7: 0 | M7: 0 | N7: 0 | O7: 0 | P7: 0 | Q7: 0 | R7: 0 | S7: 0 | T7: 0 | U7: 0 | V7: 0 | W7: 0 | X7: 0 | Y7: 0 | Z7: 0 | AA7: 0 | AB7: 0 | AC7: 0 | AD7: 0 | AE7: 0 | AF7: 0 | AG7: 0 | AH7: 0 | AI7: 0
A8: Integrin signaling | B8: 0 | C8: 0 | D8: 0 | E8: 0 | F8: 0 | G8: 1 | H8: 0 | I8: 0 | J8: 0 | K8: 0 | L8: 0 | M8: 0 | N8: 0 | O8: 0 | P8: 0 | Q8: 0 | R8: 0 | S8: 0 | T8: 0 | U8: 0 | V8: 0 | W8: 0 | X8: 0 | Y8: 0 | Z8: 0 | AA8: 0 | AB8: 0 | AC8: 0 | AD8: 0 | AE8: 0 | AF8: 0 | AG8: 0 | AH8: 0 | AI8: 0
A9: Signaling by GPCR | B9: 0 | C9: 1 | D9: 0 | E9: 0 | F9: 0 | G9: 1 | H9: 0 | I9: 0 | J9: 0 | K9: 0 | L9: 0 | M9: 0 | N9: 0 | O9: 0 | P9: 0 | Q9: 0 | R9: 0 | S9: 0 | T9: 0 | U9: 0 | V9: 0 | W9: 0 | X9: 0 | Y9: 0 | Z9: 0 | AA9: 0 | AB9: 0 | AC9: 0 | AD9: 0 | AE9: 0 | AF9: 1 | AG9: 0 | AH9: 0 | AI9: 0
A10: Signaling by Hedgehog | B10: 0 | C10: 0 | D10: 0 | E10: 0 | F10: 0 | G10: 1 | H10: 0 | I10: 0 | J10: 0 | K10: 0 | L10: 0 | M10: 0 | N10: 0 | O10: 0 | P10: 0 | Q10: 0 | R10: 0 | S10: 0 | T10: 0 | U10: 0 | V10: 0 | W10: 0 | X10: 0 | Y10: 0 | Z10: 0 | AA10: 0 | AB10: 0 | AC10: 0 | AD10: 0 | AE10: 0 | AF10: 0 | AG10: 0 | AH10: 0 | AI10: 0
A11: MAPK family signaling cascades | B11: 1 | C11: 0 | D11: 0 | E11: 0 | F11: 0 | G11: 1 | H11: 0 | I11: 0 | J11: 0 | K11: 0 | L11: 0 | M11: 0 | N11: 0 | O11: 0 | P11: 0 | Q11: 0 | R11: 0 | S11: 0 | T11: 0 | U11: 0 | V11: 0 | W11: 0 | X11: 0 | Y11: 0 | Z11: 0 | AA11: 0 | AB11: 0 | AC11: 0 | AD11: 0 | AE11: 0 | AF11: 0 | AG11: 0 | AH11: 0 | AI11: 0
A12: Death Receptor Signaling | B12: 1 | C12: 0 | D12: 0 | E12: 0 | F12: 0 | G12: 1 | H12: 0 | I12: 0 | J12: 0 | K12: 0 | L12: 0 | M12: 0 | N12: 0 | O12: 0 | P12: 0 | Q12: 0 | R12: 0 | S12: 0 | T12: 0 | U12: 0 | V12: 0 | W12: 0 | X12: 0 | Y12: 0 | Z12: 0 | AA12: 1 | AB12: 0 | AC12: 0 | AD12: 0 | AE12: 0 | AF12: 0 | AG12: 0 | AH12: 0 | AI12: 0
A13: Signaling by Erythropoietin | B13: 0 | C13: 0 | D13: 0 | E13: 0 | F13: 0 | G13: 1 | H13: 0 | I13: 0 | J13: 0 | K13: 0 | L13: 0 | M13: 0 | N13: 0 | O13: 0 | P13: 0 | Q13: 0 | R13: 0 | S13: 0 | T13: 0 | U13: 0 | V13: 0 | W13: 0 | X13: 0 | Y13: 0 | Z13: 0 | AA13: 0 | AB13: 0 | AC13: 0 | AD13: 0 | AE13: 0 | AF13: 0 | AG13: 0 | AH13: 0 | AI13: 0
A14: Intracellular signaling by second messengers | B14: 0 | C14: 0 | D14: 0 | E14: 0 | F14: 0 | G14: 1 | H14: 0 | I14: 0 | J14: 0 | K14: 0 | L14: 0 | M14: 0 | N14: 0 | O14: 0 | P14: 0 | Q14: 0 | R14: 0 | S14: 0 | T14: 0 | U14: 0 | V14: 0 | W14: 0 | X14: 0 | Y14: 0 | Z14: 0 | AA14: 0 | AB14: 0 | AC14: 0 | AD14: 0 | AE14: 0 | AF14: 0 | AG14: 0 | AH14: 0 | AI14: 0
... A406: RHOT1 GTPase cycle | B406: 0 | C406: 0 | D406: 0 | E406: 0 | F406: 0 | G406: 1 | H406: 0 | I406: 0 | J406: 0 | K406: 0 | L406: 0 | M406: 0 | N406: 0 | O406: 0 | P406: 0 | Q406: 0 | R406: 0 | S406: 0 | T406: 0 | U406: 0 | V406: 0 | W406: 0 | X406: 0 | Y406: 0 | Z406: 0 | AA406: 0 | AB406: 0 | AC406: 0 | AD406: 0 | AE406: 0 | AF406: 0 | AG406: 0 | AH406: 0 | AI406: 0

Sheet Metabolism
A1: Back to main page
A2: group | B2: ALTERS CELL PROLIFERATION AND CELL DEATH | C2: MODULATES NUCLEAR RECEPTOR-MEDIATED EFFECTS | D2: INDUCES OXIDATIVE STRESS | E2: CAUSES INFLAMMATION | F2: INDUCES EPIGENETIC ALTERATIONS | G2: ALTERS SIGNAL TRANSDUCTION | H2: CAUSES MITOCHONDRIAL DYSFUNCTION | I2: IS GENOTOXIC | J2: IS METABOLICALLY ACTIVATED OR REACTIVE | K2: ALTERS CELL-CELL INTERACTIONS AND COMMUNICATION | L2: DISRUPTS CELLULAR CYTOSKELETON | M2: IS IMMUNOSUPPRESSIVE | N2: ALTERS PRODUCTION OF HORMONE | O2: DISRUPTS LIPID AND PROTEIN METABOLISM OR CAUSES DYSLIPIDEMIA | P2: DISRUPTS TRANSPORT FUNCTION | Q2: ALTERS GERM CELL DEVELOPMENT, FUNCTION, OR DEATH | R2: AFFECTS ANTIGEN PROCESSING AND PRESENTATION | S2: ALTERS DNA REPAIR OR CAUSES GENOMIC INSTABILITY | T2: ALTERS EFFECTOR FUNCTION OF SPECIFIC CELL TYPES | U2: ALTERS HEMOSTASIS | V2: ALTERS HORMONE DISTRIBUTION OR CIRCULATING HORMONE LEVELS | W2: ALTERS HORMONE METABOLISM OR CLEARANCE | X2: ALTERS IMMUNE CELL SIGNALING | Y2: ALTERS IMMUNE CELL TRAFFICKING | Z2: BREAKS DOWN IMMUNE TOLERANCE | AA2: ACTIVATES STRESS SIGNALING PATHWAYS | AB2: CAUSES CHOLESTASIS | AC2: CAUSES IMMORTALIZATION | AD2: CAUSES LIVER FIBROSIS | AE2: IMPACTS ENDOTHELIAL AND VASCULAR FUNCTION | AF2: IMPAIRS CARDIAC CONTRACTILITY AND RELAXATION | AG2: IMPAIRS REGULATION OF CARDIAC EXCITABILITY | AH2: MODIFIES AUTONOMIC NERVOUS SYSTEM ACTIVITY | AI2: MODIFIES CELLULAR DIFFERENTIATION
A3: Mitochondrial iron-sulfur cluster biogenesis | B3: 0 | C3: 0 | D3: 0 | E3: 0 | F3: 0 | G3: 0 | H3: 1 | I3: 0 | J3: 0 | K3: 0 | L3: 0 | M3: 0 | N3: 0 | O3: 0 | P3: 0 | Q3: 0 | R3: 0 | S3: 0 | T3: 0 | U3: 0 | V3: 0 | W3: 0 | X3: 0 | Y3: 0 | Z3: 0 | AA3: 0 | AB3: 0 | AC3: 0 | AD3: 0 | AE3: 0 | AF3: 0 | AG3: 0 | AH3: 0 | AI3: 0
A4: The citric acid (TCA) cycle and respiratory electron transport | B4: 0 | C4: 0 | D4: 0 | E4: 0 | F4: 0 | G4: 0 | H4: 1 | I4: 0 | J4: 0 | K4: 0 | L4: 0 | M4: 0 | N4: 0 | O4: 1 | P4: 0 | Q4: 0 | R4: 0 | S4: 0 | T4: 0 | U4: 0 | V4: 0 | W4: 0 | X4: 0 | Y4: 0 | Z4: 0 | AA4: 0 | AB4: 0 | AC4: 0 | AD4: 0 | AE4: 0 | AF4: 0 | AG4: 0 | AH4: 0 | AI4: 0
A5: Reversible hydration of carbon dioxide | B5: 0 | C5: 0 | D5: 0 | E5: 0 | F5: 0 | G5: 0 | H5: 0 | I5: 0 | J5: 0 | K5: 0 | L5: 0 | M5: 0 | N5: 0 | O5: 0 | P5: 0 | Q5: 0 | R5: 0 | S5: 0 | T5: 0 | U5: 0 | V5: 0 | W5: 0 | X5: 0 | Y5: 0 | Z5: 0 | AA5: 0 | AB5: 0 | AC5: 0 | AD5: 0 | AE5: 0 | AF5: 0 | AG5: 0 | AH5: 0 | AI5: 0
A6: Inositol phosphate metabolism | B6: 0 | C6: 0 | D6: 0 | E6: 0 | F6: 0 | G6: 0 | H6: 0 | I6: 0 | J6: 0 | K6: 0 | L6: 0 | M6: 0 | N6: 0 | O6: 0 | P6: 0 | Q6: 0 | R6: 0 | S6: 0 | T6: 0 | U6: 0 | V6: 0 | W6: 0 | X6: 0 | Y6: 0 | Z6: 0 | AA6: 0 | AB6: 0 | AC6: 0 | AD6: 0 | AE6: 0 | AF6: 0 | AG6: 0 | AH6: 0 | AI6: 0
A7: Metabolism of nucleotides | B7: 0 | C7: 0 | D7: 0 | E7: 0 | F7: 0 | G7: 0 | H7: 0 | I7: 0 | J7: 0 | K7: 0 | L7: 0 | M7: 0 | N7: 0 | O7: 0 | P7: 0 | Q7: 0 | R7: 0 | S7: 0 | T7: 0 | U7: 0 | V7: 0 | W7: 0 | X7: 0 | Y7: 0 | Z7: 0 | AA7: 0 | AB7: 0 | AC7: 0 | AD7: 0 | AE7: 0 | AF7: 0 | AG7: 0 | AH7: 0 | AI7: 0
A8: Integration of energy metabolism | B8: 0 | C8: 0 | D8: 0 | E8: 0 | F8: 0 | G8: 0 | H8: 1 | I8: 0 | J8: 0 | K8: 0 | L8: 0 | M8: 0 | N8: 0 | O8: 0 | P8: 0 | Q8: 0 | R8: 0 | S8: 0 | T8: 0 | U8: 0 | V8: 0 | W8: 0 | X8: 0 | Y8: 0 | Z8: 0 | AA8: 0 | AB8: 0 | AC8: 0 | AD8: 0 | AE8: 0 | AF8: 0 | AG8: 0 | AH8: 0 | AI8: 0
A9: Metabolism of porphyrins | B9: 0 | C9: 0 | D9: 0 | E9: 0 | F9: 0 | G9: 0 | H9: 0 | I9: 0 | J9: 0 | K9: 0 | L9: 0 | M9: 0 | N9: 0 | O9: 0 | P9: 0 | Q9: 0 | R9: 0 | S9: 0 | T9: 0 | U9: 0 | V9: 0 | W9: 0 | X9: 0 | Y9: 0 | Z9: 0 | AA9: 0 | AB9: 0 | AC9: 0 | AD9: 0 | AE9: 0 | AF9: 0 | AG9: 0 | AH9: 0 | AI9: 0
A10: Metabolism of vitamins and cofactors | B10: 0 | C10: 0 | D10: 0 | E10: 0 | F10: 0 | G10: 0 | H10: 0 | I10: 0 | J10: 0 | K10: 0 | L10: 0 | M10: 0 | N10: 0 | O10: 0 | P10: 0 | Q10: 0 | R10: 0 | S10: 0 | T10: 0 | U10: 0 | V10: 0 | W10: 0 | X10: 0 | Y10: 0 | Z10: 0 | AA10: 0 | AB10: 0 | AC10: 0 | AD10: 0 | AE10: 0 | AF10: 0 | AG10: 0 | AH10: 0 | AI10: 0
A11: Metabolism of nitric oxide: NOS3 activation and regulation | B11: 0 | C11: 0 | D11: 0 | E11: 0 | F11: 0 | G11: 0 | H11: 0 | I11: 0 | J11: 0 | K11: 0 | L11: 0 | M11: 0 | N11: 0 | O11: 0 | P11: 0 | Q11: 0 | R11: 0 | S11: 0 | T11: 0 | U11: 0 | V11: 0 | W11: 0 | X11: 0 | Y11: 0 | Z11: 0 | AA11: 0 | AB11: 0 | AC11: 0 | AD11: 0 | AE11: 0 | AF11: 0 | AG11: 0 | AH11: 0 | AI11: 0
A12: Biological oxidations | B12: 0 | C12: 0 | D12: 1 | E12: 0 | F12: 0 | G12: 0 | H12: 0 | I12: 0 | J12: 0 | K12: 0 | L12: 0 | M12: 0 | N12: 0 | O12: 0 | P12: 0 | Q12: 0 | R12: 0 | S12: 0 | T12: 0 | U12: 0 | V12: 0 | W12: 0 | X12: 0 | Y12: 0 | Z12: 0 | AA12: 0 | AB12: 0 | AC12: 0 | AD12: 0 | AE12: 0 | AF12: 0 | AG12: 0 | AH12: 0 | AI12: 0
A13: Cytosolic iron-sulfur cluster assembly | B13: 0 | C13: 0 | D13: 0 | E13: 0 | F13: 0 | G13: 0 | H13: 0 | I13: 0 | J13: 0 | K13: 0 | L13: 0 | M13: 0 | N13: 0 | O13: 0 | P13: 0 | Q13: 0 | R13: 0 | S13: 0 | T13: 0 | U13: 0 | V13: 0 | W13: 0 | X13: 0 | Y13: 0 | Z13: 0 | AA13: 0 | AB13: 0 | AC13: 0 | AD13: 0 | AE13: 0 | AF13: 0 | AG13: 0 | AH13: 0 | AI13: 0
A14: Metabolism of lipids | B14: 0 | C14: 0 | D14: 0 | E14: 0 | F14: 0 | G14: 0 | H14: 0 | I14: 0 | J14: 0 | K14: 0 | L14: 0 | M14: 0 | N14: 0 | O14: 1 | P14: 0 | Q14: 0 | R14: 0 | S14: 0 | T14: 0 | U14: 0 | V14: 0 | W14: 0 | X14: 0 | Y14: 0 | Z14: 0 | AA14: 0 | AB14: 0 | AC14: 0 | AD14: 0 | AE14: 0 | AF14: 0 | AG14: 0 | AH14: 0 | AI14: 0
... A329: Lewis blood group biosynthesis | B329: 0 | C329: 0 | D329: 0 | E329: 0 | F329: 0 | G329: 0 | H329: 0 | I329: 0 | J329: 0 | K329: 0 | L329: 0 | M329: 0 | N329: 0 | O329: 0 | P329: 0 | Q329: 0 | R329: 0 | S329: 0 | T329: 0 | U329: 0 | V329: 0 | W329: 0 | X329: 0 | Y329: 0 | Z329: 0 | AA329: 0 | AB329: 0 | AC329: 0 | AD329: 0 | AE329: 0 | AF329: 0 | AG329: 0 | AH329: 0 | AI329: 0

Sheet Immune System
A1: Back to main page
A2: group | B2: ALTERS CELL PROLIFERATION AND CELL DEATH | C2: MODULATES NUCLEAR RECEPTOR-MEDIATED EFFECTS | D2: INDUCES OXIDATIVE STRESS | E2: CAUSES INFLAMMATION | F2: INDUCES EPIGENETIC ALTERATIONS | G2: ALTERS SIGNAL TRANSDUCTION | H2: CAUSES MITOCHONDRIAL DYSFUNCTION | I2: IS GENOTOXIC | J2: IS METABOLICALLY ACTIVATED OR REACTIVE | K2: ALTERS CELL-CELL INTERACTIONS AND COMMUNICATION | L2: DISRUPTS CELLULAR CYTOSKELETON | M2: IS IMMUNOSUPPRESSIVE | N2: ALTERS PRODUCTION OF HORMONE | O2: DISRUPTS LIPID AND PROTEIN METABOLISM OR CAUSES DYSLIPIDEMIA | P2: DISRUPTS TRANSPORT FUNCTION | Q2: ALTERS GERM CELL DEVELOPMENT, FUNCTION, OR DEATH | R2: AFFECTS ANTIGEN PROCESSING AND PRESENTATION | S2: ALTERS DNA REPAIR OR CAUSES GENOMIC INSTABILITY | T2: ALTERS EFFECTOR FUNCTION OF SPECIFIC CELL TYPES | U2: ALTERS HEMOSTASIS | V2: ALTERS HORMONE DISTRIBUTION OR CIRCULATING HORMONE LEVELS | W2: ALTERS HORMONE METABOLISM OR CLEARANCE | X2: ALTERS IMMUNE CELL SIGNALING | Y2: ALTERS IMMUNE CELL TRAFFICKING | Z2: BREAKS DOWN IMMUNE TOLERANCE | AA2: ACTIVATES STRESS SIGNALING PATHWAYS | AB2: CAUSES CHOLESTASIS | AC2: CAUSES IMMORTALIZATION | AD2: CAUSES LIVER FIBROSIS | AE2: IMPACTS ENDOTHELIAL AND VASCULAR FUNCTION | AF2: IMPAIRS CARDIAC CONTRACTILITY AND RELAXATION | AG2: IMPAIRS REGULATION OF CARDIAC EXCITABILITY | AH2: MODIFIES AUTONOMIC NERVOUS SYSTEM ACTIVITY | AI2: MODIFIES CELLULAR DIFFERENTIATION
A3: Cytokine Signaling in Immune system | B3: 0 | C3: 0 | D3: 0 | E3: 1 | F3: 0 | G3: 0 | H3: 0 | I3: 0 | J3: 0 | K3: 0 | L3: 0 | M3: 0 | N3: 0 | O3: 0 | P3: 0 | Q3: 0 | R3: 0 | S3: 0 | T3: 0 | U3: 0 | V3: 0 | W3: 0 | X3: 1 | Y3: 0 | Z3: 0 | AA3: 0 | AB3: 0 | AC3: 0 | AD3: 0 | AE3: 0 | AF3: 0 | AG3: 0 | AH3: 0 | AI3: 0
A4: Adaptive Immune System | B4: 0 | C4: 0 | D4: 0 | E4: 1 | F4: 0 | G4: 0 | H4: 0 | I4: 0 | J4: 0 | K4: 0 | L4: 0 | M4: 0 | N4: 0 | O4: 0 | P4: 0 | Q4: 0 | R4: 0 | S4: 0 | T4: 0 | U4: 0 | V4: 0 | W4: 0 | X4: 0 | Y4: 0 | Z4: 0 | AA4: 0 | AB4: 0 | AC4: 0 | AD4: 0 | AE4: 0 | AF4: 0 | AG4: 0 | AH4: 0 | AI4: 0
A5: Innate Immune System | B5: 0 | C5: 0 | D5: 0 | E5: 1 | F5: 0 | G5: 0 | H5: 0 | I5: 0 | J5: 0 | K5: 0 | L5: 0 | M5: 0 | N5: 0 | O5: 0 | P5: 0 | Q5: 0 | R5: 0 | S5: 0 | T5: 1 | U5: 0 | V5: 0 | W5: 0 | X5: 0 | Y5: 0 | Z5: 0 | AA5: 0 | AB5: 0 | AC5: 0 | AD5: 0 | AE5: 0 | AF5: 0 | AG5: 0 | AH5: 0 | AI5: 0
A6: Prolactin receptor signaling | B6: 0 | C6: 0 | D6: 0 | E6: 1 | F6: 0 | G6: 0 | H6: 0 | I6: 0 | J6: 0 | K6: 0 | L6: 0 | M6: 0 | N6: 0 | O6: 0 | P6: 0 | Q6: 0 | R6: 0 | S6: 0 | T6: 0 | U6: 0 | V6: 0 | W6: 0 | X6: 1 | Y6: 0 | Z6: 0 | AA6: 0 | AB6: 0 | AC6: 0 | AD6: 0 | AE6: 0 | AF6: 0 | AG6: 0 | AH6: 0 | AI6: 0
A7: Signaling by Interleukins | B7: 0 | C7: 0 | D7: 0 | E7: 1 | F7: 0 | G7: 0 | H7: 0 | I7: 0 | J7: 0 | K7: 0 | L7: 0 | M7: 0 | N7: 0 | O7: 0 | P7: 0 | Q7: 0 | R7: 0 | S7: 0 | T7: 0 | U7: 0 | V7: 0 | W7: 0 | X7: 1 | Y7: 0 | Z7: 0 | AA7: 0 | AB7: 0 | AC7: 0 | AD7: 0 | AE7: 0 | AF7: 0 | AG7: 0 | AH7: 0 | AI7: 0
A8: TNFR2 non-canonical NF-kB pathway | B8: 0 | C8: 0 | D8: 0 | E8: 1 | F8: 0 | G8: 0 | H8: 0 | I8: 0 | J8: 0 | K8: 0 | L8: 0 | M8: 0 | N8: 0 | O8: 0 | P8: 0 | Q8: 0 | R8: 0 | S8: 0 | T8: 0 | U8: 0 | V8: 0 | W8: 0 | X8: 1 | Y8: 0 | Z8: 0 | AA8: 0 | AB8: 0 | AC8: 0 | AD8: 0 | AE8: 0 | AF8: 0 | AG8: 0 | AH8: 0 | AI8: 0
A9: Interferon Signaling | B9: 0 | C9: 0 | D9: 0 | E9: 1 | F9: 0 | G9: 0 | H9: 0 | I9: 0 | J9: 0 | K9: 0 | L9: 0 | M9: 0 | N9: 0 | O9: 0 | P9: 0 | Q9: 0 | R9: 0 | S9: 0 | T9: 0 | U9: 0 | V9: 0 | W9: 0 | X9: 1 | Y9: 0 | Z9: 0 | AA9: 0 | AB9: 0 | AC9: 0 | AD9: 0 | AE9: 0 | AF9: 0 | AG9: 0 | AH9: 0 | AI9: 0
A10: FLT3 Signaling | B10: 0 | C10: 0 | D10: 0 | E10: 1 | F10: 0 | G10: 0 | H10: 0 | I10: 0 | J10: 0 | K10: 0 | L10: 0 | M10: 0 | N10: 0 | O10: 0 | P10: 0 | Q10: 0 | R10: 0 | S10: 0 | T10: 0 | U10: 0 | V10: 0 | W10: 0 | X10: 1 | Y10: 0 | Z10: 0 | AA10: 0 | AB10: 0 | AC10: 0 | AD10: 0 | AE10: 0 | AF10: 0 | AG10: 0 | AH10: 0 | AI10: 0
A11: Signaling by CSF3 (G-CSF) | B11: 0 | C11: 0 | D11: 0 | E11: 1 | F11: 0 | G11: 0 | H11: 0 | I11: 0 | J11: 0 | K11: 0 | L11: 0 | M11: 0 | N11: 0 | O11: 0 | P11: 0 | Q11: 0 | R11: 0 | S11: 0 | T11: 0 | U11: 0 | V11: 0 | W11: 0 | X11: 1 | Y11: 0 | Z11: 0 | AA11: 0 | AB11: 0 | AC11: 0 | AD11: 0 | AE11: 0 | AF11: 0 | AG11: 0 | AH11: 0 | AI11: 0
A12: Signaling by CSF1 (M-CSF) in myeloid cells | B12: 0 | C12: 0 | D12: 0 | E12: 1 | F12: 0 | G12: 0 | H12: 0 | I12: 0 | J12: 0 | K12: 0 | L12: 0 | M12: 0 | N12: 0 | O12: 0 | P12: 0 | Q12: 0 | R12: 0 | S12: 0 | T12: 0 | U12: 0 | V12: 0 | W12: 0 | X12: 1 | Y12: 0 | Z12: 0 | AA12: 0 | AB12: 0 | AC12: 0 | AD12: 0 | AE12: 0 | AF12: 0 | AG12: 0 | AH12: 0 | AI12: 0
A13: Growth hormone receptor signaling | B13: 0 | C13: 0 | D13: 0 | E13: 1 | F13: 0 | G13: 0 | H13: 0 | I13: 0 | J13: 0 | K13: 0 | L13: 0 | M13: 0 | N13: 0 | O13: 0 | P13: 0 | Q13: 0 | R13: 0 | S13: 0 | T13: 0 | U13: 0 | V13: 0 | W13: 0 | X13: 1 | Y13: 0 | Z13: 0 | AA13: 0 | AB13: 0 | AC13: 0 | AD13: 0 | AE13: 0 | AF13: 0 | AG13: 0 | AH13: 0 | AI13: 0
A14: Interleukin-7 signaling | B14: 0 | C14: 0 | D14: 0 | E14: 1 | F14: 0 | G14: 0 | H14: 0 | I14: 0 | J14: 0 | K14: 0 | L14: 0 | M14: 0 | N14: 0 | O14: 0 | P14: 0 | Q14: 0 | R14: 0 | S14: 0 | T14: 0 | U14: 0 | V14: 0 | W14: 0 | X14: 1 | Y14: 0 | Z14: 0 | AA14: 0 | AB14: 0 | AC14: 0 | AD14: 0 | AE14: 0 | AF14: 0 | AG14: 0 | AH14: 0 | AI14: 0
... A197: Immune System | B197: 0 | C197: 0 | D197: 0 | E197: 1 | F197: 0 | G197: 0 | H197: 0 | I197: 0 | J197: 0 | K197: 0 | L197: 0 | M197: 0 | N197: 0 | O197: 0 | P197: 0 | Q197: 0 | R197: 0 | S197: 0 | T197: 1 | U197: 0 | V197: 0 | W197: 0 | X197: 0 | Y197: 0 | Z197: 0 | AA197: 0 | AB197: 0 | AC197: 0 | AD197: 0 | AE197: 0 | AF197: 0 | AG197: 0 | AH197: 0 | AI197: 0

Sheet Cell Cycle
A1: Back to main page
A2: group | B2: ALTERS CELL PROLIFERATION AND CELL DEATH | C2: MODULATES NUCLEAR RECEPTOR-MEDIATED EFFECTS | D2: INDUCES OXIDATIVE STRESS | E2: CAUSES INFLAMMATION | F2: INDUCES EPIGENETIC ALTERATIONS | G2: ALTERS SIGNAL TRANSDUCTION | H2: CAUSES MITOCHONDRIAL DYSFUNCTION | I2: IS GENOTOXIC | J2: IS METABOLICALLY ACTIVATED OR REACTIVE | K2: ALTERS CELL-CELL INTERACTIONS AND COMMUNICATION | L2: DISRUPTS CELLULAR CYTOSKELETON | M2: IS IMMUNOSUPPRESSIVE | N2: ALTERS PRODUCTION OF HORMONE | O2: DISRUPTS LIPID AND PROTEIN METABOLISM OR CAUSES DYSLIPIDEMIA | P2: DISRUPTS TRANSPORT FUNCTION | Q2: ALTERS GERM CELL DEVELOPMENT, FUNCTION, OR DEATH | R2: AFFECTS ANTIGEN PROCESSING AND PRESENTATION | S2: ALTERS DNA REPAIR OR CAUSES GENOMIC INSTABILITY | T2: ALTERS EFFECTOR FUNCTION OF SPECIFIC CELL TYPES | U2: ALTERS HEMOSTASIS | V2: ALTERS HORMONE DISTRIBUTION OR CIRCULATING HORMONE LEVELS | W2: ALTERS HORMONE METABOLISM OR CLEARANCE | X2: ALTERS IMMUNE CELL SIGNALING | Y2: ALTERS IMMUNE CELL TRAFFICKING | Z2: BREAKS DOWN IMMUNE TOLERANCE | AA2: ACTIVATES STRESS SIGNALING PATHWAYS | AB2: CAUSES CHOLESTASIS | AC2: CAUSES IMMORTALIZATION | AD2: CAUSES LIVER FIBROSIS | AE2: IMPACTS ENDOTHELIAL AND VASCULAR FUNCTION | AF2: IMPAIRS CARDIAC CONTRACTILITY AND RELAXATION | AG2: IMPAIRS REGULATION OF CARDIAC EXCITABILITY | AH2: MODIFIES AUTONOMIC NERVOUS SYSTEM ACTIVITY | AI2: MODIFIES CELLULAR DIFFERENTIATION
A3: Meiosis | B3: 0 | C3: 0 | D3: 0 | E3: 0 | F3: 0 | G3: 0 | H3: 0 | I3: 0 | J3: 0 | K3: 0 | L3: 0 | M3: 0 | N3: 0 | O3: 0 | P3: 0 | Q3: 1 | R3: 0 | S3: 0 | T3: 0 | U3: 0 | V3: 0 | W3: 0 | X3: 0 | Y3: 0 | Z3: 0 | AA3: 0 | AB3: 0 | AC3: 0 | AD3: 0 | AE3: 0 | AF3: 0 | AG3: 0 | AH3: 0 | AI3: 0
A4: Cell Cycle, Mitotic | B4: 1 | C4: 0 | D4: 0 | E4: 0 | F4: 0 | G4: 0 | H4: 0 | I4: 0 | J4: 0 | K4: 0 | L4: 0 | M4: 0 | N4: 0 | O4: 0 | P4: 0 | Q4: 0 | R4: 0 | S4: 0 | T4: 0 | U4: 0 | V4: 0 | W4: 0 | X4: 0 | Y4: 0 | Z4: 0 | AA4: 0 | AB4: 0 | AC4: 0 | AD4: 0 | AE4: 0 | AF4: 0 | AG4: 0 | AH4: 0 | AI4: 0
A5: Cell Cycle Checkpoints | B5: 1 | C5: 0 | D5: 0 | E5: 0 | F5: 0 | G5: 0 | H5: 0 | I5: 0 | J5: 0 | K5: 0 | L5: 0 | M5: 0 | N5: 0 | O5: 0 | P5: 0 | Q5: 0 | R5: 0 | S5: 0 | T5: 0 | U5: 0 | V5: 0 | W5: 0 | X5: 0 | Y5: 0 | Z5: 0 | AA5: 0 | AB5: 0 | AC5: 0 | AD5: 0 | AE5: 0 | AF5: 0 | AG5: 0 | AH5: 0 | AI5: 0
A6: Chromosome Maintenance | B6: 1 | C6: 0 | D6: 0 | E6: 0 | F6: 0 | G6: 0 | H6: 0 | I6: 0 | J6: 0 | K6: 0 | L6: 0 | M6: 0 | N6: 0 | O6: 0 | P6: 0 | Q6: 0 | R6: 0 | S6: 0 | T6: 0 | U6: 0 | V6: 0 | W6: 0 | X6: 0 | Y6: 0 | Z6: 0 | AA6: 0 | AB6: 0 | AC6: 0 | AD6: 0 | AE6: 0 | AF6: 0 | AG6: 0 | AH6: 0 | AI6: 0
A7: Meiotic synapsis | B7: 0 | C7: 0 | D7: 0 | E7: 0 | F7: 0 | G7: 0 | H7: 0 | I7: 0 | J7: 0 | K7: 0 | L7: 0 | M7: 0 | N7: 0 | O7: 0 | P7: 0 | Q7: 1 | R7: 0 | S7: 0 | T7: 0 | U7: 0 | V7: 0 | W7: 0 | X7: 0 | Y7: 0 | Z7: 0 | AA7: 0 | AB7: 0 | AC7: 0 | AD7: 0 | AE7: 0 | AF7: 0 | AG7: 0 | AH7: 0 | AI7: 0
A8: Meiotic recombination | B8: 0 | C8: 0 | D8: 0 | E8: 0 | F8: 0 | G8: 0 | H8: 0 | I8: 0 | J8: 0 | K8: 0 | L8: 0 | M8: 0 | N8: 0 | O8: 0 | P8: 0 | Q8: 1 | R8: 0 | S8: 0 | T8: 0 | U8: 0 | V8: 0 | W8: 0 | X8: 0 | Y8: 0 | Z8: 0 | AA8: 0 | AB8: 0 | AC8: 0 | AD8: 0 | AE8: 0 | AF8: 0 | AG8: 0 | AH8: 0 | AI8: 0
A9: Mitotic G2-G2/M phases | B9: 1 | C9: 0 | D9: 0 | E9: 0 | F9: 0 | G9: 0 | H9: 0 | I9: 0 | J9: 0 | K9: 0 | L9: 0 | M9: 0 | N9: 0 | O9: 0 | P9: 0 | Q9: 0 | R9: 0 | S9: 0 | T9: 0 | U9: 0 | V9: 0 | W9: 0 | X9: 0 | Y9: 0 | Z9: 0 | AA9: 0 | AB9: 0 | AC9: 0 | AD9: 0 | AE9: 0 | AF9: 0 | AG9: 0 | AH9: 0 | AI9: 0
A10: Regulation of mitotic cell cycle | B10: 1 | C10: 0 | D10: 0 | E10: 0 | F10: 0 | G10: 0 | H10: 0 | I10: 0 | J10: 0 | K10: 0 | L10: 0 | M10: 0 | N10: 0 | O10: 0 | P10: 0 | Q10: 0 | R10: 0 | S10: 0 | T10: 0 | U10: 0 | V10: 0 | W10: 0 | X10: 0 | Y10: 0 | Z10: 0 | AA10: 0 | AB10: 0 | AC10: 0 | AD10: 0 | AE10: 0 | AF10: 0 | AG10: 0 | AH10: 0 | AI10: 0
A11: Mitotic G1 phase and G1/S transition | B11: 1 | C11: 0 | D11: 0 | E11: 0 | F11: 0 | G11: 0 | H11: 0 | I11: 0 | J11: 0 | K11: 0 | L11: 0 | M11: 0 | N11: 0 | O11: 0 | P11: 0 | Q11: 0 | R11: 0 | S11: 0 | T11: 0 | U11: 0 | V11: 0 | W11: 0 | X11: 0 | Y11: 0 | Z11: 0 | AA11: 0 | AB11: 0 | AC11: 0 | AD11: 0 | AE11: 0 | AF11: 0 | AG11: 0 | AH11: 0 | AI11: 0
A12: M Phase | B12: 1 | C12: 0 | D12: 0 | E12: 0 | F12: 0 | G12: 0 | H12: 0 | I12: 0 | J12: 0 | K12: 0 | L12: 0 | M12: 0 | N12: 0 | O12: 0 | P12: 0 | Q12: 0 | R12: 0 | S12: 0 | T12: 0 | U12: 0 | V12: 0 | W12: 0 | X12: 0 | Y12: 0 | Z12: 0 | AA12: 0 | AB12: 0 | AC12: 0 | AD12: 0 | AE12: 0 | AF12: 0 | AG12: 0 | AH12: 0 | AI12: 0
A13: S Phase | B13: 1 | C13: 0 | D13: 0 | E13: 0 | F13: 0 | G13: 0 | H13: 0 | I13: 0 | J13: 0 | K13: 0 | L13: 0 | M13: 0 | N13: 0 | O13: 0 | P13: 0 | Q13: 0 | R13: 0 | S13: 0 | T13: 0 | U13: 0 | V13: 0 | W13: 0 | X13: 0 | Y13: 0 | Z13: 0 | AA13: 0 | AB13: 0 | AC13: 0 | AD13: 0 | AE13: 0 | AF13: 0 | AG13: 0 | AH13: 0 | AI13: 0
A14: G2 Phase | B14: 1 | C14: 0 | D14: 0 | E14: 0 | F14: 0 | G14: 0 | H14: 0 | I14: 0 | J14: 0 | K14: 0 | L14: 0 | M14: 0 | N14: 0 | O14: 0 | P14: 0 | Q14: 0 | R14: 0 | S14: 0 | T14: 0 | U14: 0 | V14: 0 | W14: 0 | X14: 0 | Y14: 0 | Z14: 0 | AA14: 0 | AB14: 0 | AC14: 0 | AD14: 0 | AE14: 0 | AF14: 0 | AG14: 0 | AH14: 0 | AI14: 0
... A128: Cell Cycle | B128: 1 | C128: 0 | D128: 0 | E128: 0 | F128: 0 | G128: 0 | H128: 0 | I128: 0 | J128: 0 | K128: 0 | L128: 0 | M128: 0 | N128: 0 | O128: 0 | P128: 0 | Q128: 0 | R128: 0 | S128: 0 | T128: 0 | U128: 0 | V128: 0 | W128: 0 | X128: 0 | Y128: 0 | Z128: 0 | AA128: 0 | AB128: 0 | AC128: 0 | AD128: 0 | AE128: 0 | AF128: 0 | AG128: 0 | AH128: 0 | AI128: 0

Sheet Gene expression (Transcription)
A1: Back to main page
A2: group | B2: ALTERS CELL PROLIFERATION AND CELL DEATH | C2: MODULATES NUCLEAR RECEPTOR-MEDIATED EFFECTS | D2: INDUCES OXIDATIVE STRESS | E2: CAUSES INFLAMMATION | F2: INDUCES EPIGENETIC ALTERATIONS | G2: ALTERS SIGNAL TRANSDUCTION | H2: CAUSES MITOCHONDRIAL DYSFUNCTION | I2: IS GENOTOXIC | J2: IS METABOLICALLY ACTIVATED OR REACTIVE | K2: ALTERS CELL-CELL INTERACTIONS AND COMMUNICATION | L2: DISRUPTS CELLULAR CYTOSKELETON | M2: IS IMMUNOSUPPRESSIVE | N2: ALTERS PRODUCTION OF HORMONE | O2: DISRUPTS LIPID AND PROTEIN METABOLISM OR CAUSES DYSLIPIDEMIA | P2: DISRUPTS TRANSPORT FUNCTION | Q2: ALTERS GERM CELL DEVELOPMENT, FUNCTION, OR DEATH | R2: AFFECTS ANTIGEN PROCESSING AND PRESENTATION | S2: ALTERS DNA REPAIR OR CAUSES GENOMIC INSTABILITY | T2: ALTERS EFFECTOR FUNCTION OF SPECIFIC CELL TYPES | U2: ALTERS HEMOSTASIS | V2: ALTERS HORMONE DISTRIBUTION OR CIRCULATING HORMONE LEVELS | W2: ALTERS HORMONE METABOLISM OR CLEARANCE | X2: ALTERS IMMUNE CELL SIGNALING | Y2: ALTERS IMMUNE CELL TRAFFICKING | Z2: BREAKS DOWN IMMUNE TOLERANCE | AA2: ACTIVATES STRESS SIGNALING PATHWAYS | AB2: CAUSES CHOLESTASIS | AC2: CAUSES IMMORTALIZATION | AD2: CAUSES LIVER FIBROSIS | AE2: IMPACTS ENDOTHELIAL AND VASCULAR FUNCTION | AF2: IMPAIRS CARDIAC CONTRACTILITY AND RELAXATION | AG2: IMPAIRS REGULATION OF CARDIAC EXCITABILITY | AH2: MODIFIES AUTONOMIC NERVOUS SYSTEM ACTIVITY | AI2: MODIFIES CELLULAR DIFFERENTIATION
A3: Gene Silencing by RNA | B3: 0 | C3: 0 | D3: 0 | E3: 0 | F3: 0 | G3: 0 | H3: 0 | I3: 0 | J3: 0 | K3: 0 | L3: 0 | M3: 0 | N3: 0 | O3: 0 | P3: 0 | Q3: 0 | R3: 0 | S3: 0 | T3: 0 | U3: 0 | V3: 0 | W3: 0 | X3: 0 | Y3: 0 | Z3: 0 | AA3: 0 | AB3: 0 | AC3: 0 | AD3: 0 | AE3: 0 | AF3: 0 | AG3: 0 | AH3: 0 | AI3: 0
A4: Epigenetic regulation of gene expression | B4: 0 | C4: 0 | D4: 0 | E4: 0 | F4: 1 | G4: 0 | H4: 0 | I4: 0 | J4: 0 | K4: 0 | L4: 0 | M4: 0 | N4: 0 | O4: 0 | P4: 0 | Q4: 0 | R4: 0 | S4: 0 | T4: 0 | U4: 0 | V4: 0 | W4: 0 | X4: 0 | Y4: 0 | Z4: 0 | AA4: 0 | AB4: 0 | AC4: 0 | AD4: 0 | AE4: 0 | AF4: 0 | AG4: 0 | AH4: 0 | AI4: 0
A5: RNA Polymerase II Transcription | B5: 0 | C5: 0 | D5: 0 | E5: 0 | F5: 0 | G5: 0 | H5: 0 | I5: 0 | J5: 0 | K5: 0 | L5: 0 | M5: 0 | N5: 0 | O5: 0 | P5: 0 | Q5: 0 | R5: 0 | S5: 0 | T5: 0 | U5: 0 | V5: 0 | W5: 0 | X5: 0 | Y5: 0 | Z5: 0 | AA5: 0 | AB5: 0 | AC5: 0 | AD5: 0 | AE5: 0 | AF5: 0 | AG5: 0 | AH5: 0 | AI5: 0
A6: RNA Polymerase I Transcription | B6: 0 | C6: 0 | D6: 0 | E6: 0 | F6: 0 | G6: 0 | H6: 0 | I6: 0 | J6: 0 | K6: 0 | L6: 0 | M6: 0 | N6: 0 | O6: 0 | P6: 0 | Q6: 0 | R6: 0 | S6: 0 | T6: 0 | U6: 0 | V6: 0 | W6: 0 | X6: 0 | Y6: 0 | Z6: 0 | AA6: 0 | AB6: 0 | AC6: 0 | AD6: 0 | AE6: 0 | AF6: 0 | AG6: 0 | AH6: 0 | AI6: 0
A7: RNA Polymerase III Transcription | B7: 0 | C7: 0 | D7: 0 | E7: 0 | F7: 0 | G7: 0 | H7: 0 | I7: 0 | J7: 0 | K7: 0 | L7: 0 | M7: 0 | N7: 0 | O7: 0 | P7: 0 | Q7: 0 | R7: 0 | S7: 0 | T7: 0 | U7: 0 | V7: 0 | W7: 0 | X7: 0 | Y7: 0 | Z7: 0 | AA7: 0 | AB7: 0 | AC7: 0 | AD7: 0 | AE7: 0 | AF7: 0 | AG7: 0 | AH7: 0 | AI7: 0
A8: Transcription from mitochondrial promoters | B8: 0 | C8: 0 | D8: 0 | E8: 0 | F8: 0 | G8: 0 | H8: 1 | I8: 0 | J8: 0 | K8: 0 | L8: 0 | M8: 0 | N8: 0 | O8: 0 | P8: 0 | Q8: 0 | R8: 0 | S8: 0 | T8: 0 | U8: 0 | V8: 0 | W8: 0 | X8: 0 | Y8: 0 | Z8: 0 | AA8: 0 | AB8: 0 | AC8: 0 | AD8: 0 | AE8: 0 | AF8: 0 | AG8: 0 | AH8: 0 | AI8: 0
A9: MicroRNA (miRNA) biogenesis | B9: 0 | C9: 0 | D9: 0 | E9: 0 | F9: 0 | G9: 0 | H9: 0 | I9: 0 | J9: 0 | K9: 0 | L9: 0 | M9: 0 | N9: 0 | O9: 0 | P9: 0 | Q9: 0 | R9: 0 | S9: 0 | T9: 0 | U9: 0 | V9: 0 | W9: 0 | X9: 0 | Y9: 0 | Z9: 0 | AA9: 0 | AB9: 0 | AC9: 0 | AD9: 0 | AE9: 0 | AF9: 0 | AG9: 0 | AH9: 0 | AI9: 0
A10: Small interfering RNA (siRNA) biogenesis | B10: 0 | C10: 0 | D10: 0 | E10: 0 | F10: 0 | G10: 0 | H10: 0 | I10: 0 | J10: 0 | K10: 0 | L10: 0 | M10: 0 | N10: 0 | O10: 0 | P10: 0 | Q10: 0 | R10: 0 | S10: 0 | T10: 0 | U10: 0 | V10: 0 | W10: 0 | X10: 0 | Y10: 0 | Z10: 0 | AA10: 0 | AB10: 0 | AC10: 0 | AD10: 0 | AE10: 0 | AF10: 0 | AG10: 0 | AH10: 0 | AI10: 0
A11: Post-transcriptional silencing by small RNAs | B11: 0 | C11: 0 | D11: 0 | E11: 0 | F11: 0 | G11: 0 | H11: 0 | I11: 0 | J11: 0 | K11: 0 | L11: 0 | M11: 0 | N11: 0 | O11: 0 | P11: 0 | Q11: 0 | R11: 0 | S11: 0 | T11: 0 | U11: 0 | V11: 0 | W11: 0 | X11: 0 | Y11: 0 | Z11: 0 | AA11: 0 | AB11: 0 | AC11: 0 | AD11: 0 | AE11: 0 | AF11: 0 | AG11: 0 | AH11: 0 | AI11: 0
A12: Transcriptional regulation by small RNAs | B12: 0 | C12: 0 | D12: 0 | E12: 0 | F12: 0 | G12: 0 | H12: 0 | I12: 0 | J12: 0 | K12: 0 | L12: 0 | M12: 0 | N12: 0 | O12: 0 | P12: 0 | Q12: 0 | R12: 0 | S12: 0 | T12: 0 | U12: 0 | V12: 0 | W12: 0 | X12: 0 | Y12: 0 | Z12: 0 | AA12: 0 | AB12: 0 | AC12: 0 | AD12: 0 | AE12: 0 | AF12: 0 | AG12: 0 | AH12: 0 | AI12: 0
A13: PIWI-interacting RNA (piRNA) biogenesis | B13: 0 | C13: 0 | D13: 0 | E13: 0 | F13: 0 | G13: 0 | H13: 0 | I13: 0 | J13: 0 | K13: 0 | L13: 0 | M13: 0 | N13: 0 | O13: 0 | P13: 0 | Q13: 0 | R13: 0 | S13: 0 | T13: 0 | U13: 0 | V13: 0 | W13: 0 | X13: 0 | Y13: 0 | Z13: 0 | AA13: 0 | AB13: 0 | AC13: 0 | AD13: 0 | AE13: 0 | AF13: 0 | AG13: 0 | AH13: 0 | AI13: 0
A14: tRNA-derived small RNA (tsRNA or tRNA-related fragment, tRF) biogenesis | B14: 0 | C14: 0 | D14: 0 | E14: 0 | F14: 0 | G14: 0 | H14: 0 | I14: 0 | J14: 0 | K14: 0 | L14: 0 | M14: 0 | N14: 0 | O14: 0 | P14: 0 | Q14: 0 | R14: 0 | S14: 0 | T14: 0 | U14: 0 | V14: 0 | W14: 0 | X14: 0 | Y14: 0 | Z14: 0 | AA14: 0 | AB14: 0 | AC14: 0 | AD14: 0 | AE14: 0 | AF14: 0 | AG14: 0 | AH14: 0 | AI14: 0
... A133: Mitochondrial transcription termination | B133: 0 | C133: 0 | D133: 0 | E133: 0 | F133: 0 | G133: 0 | H133: 1 | I133: 0 | J133: 0 | K133: 0 | L133: 0 | M133: 0 | N133: 0 | O133: 0 | P133: 0 | Q133: 0 | R133: 0 | S133: 0 | T133: 0 | U133: 0 | V133: 0 | W133: 0 | X133: 0 | Y133: 0 | Z133: 0 | AA133: 0 | AB133: 0 | AC133: 0 | AD133: 0 | AE133: 0 | AF133: 0 | AG133: 0 | AH133: 0 | AI133: 0

Sheet Metabolism of proteins
A1: Back to main page
A2: group | B2: ALTERS CELL PROLIFERATION AND CELL DEATH | C2: MODULATES NUCLEAR RECEPTOR-MEDIATED EFFECTS | D2: INDUCES OXIDATIVE STRESS | E2: CAUSES INFLAMMATION | F2: INDUCES EPIGENETIC ALTERATIONS | G2: ALTERS SIGNAL TRANSDUCTION | H2: CAUSES MITOCHONDRIAL DYSFUNCTION | I2: IS GENOTOXIC | J2: IS METABOLICALLY ACTIVATED OR REACTIVE | K2: ALTERS CELL-CELL INTERACTIONS AND COMMUNICATION | L2: DISRUPTS CELLULAR CYTOSKELETON | M2: IS IMMUNOSUPPRESSIVE | N2: ALTERS PRODUCTION OF HORMONE | O2: DISRUPTS LIPID AND PROTEIN METABOLISM OR CAUSES DYSLIPIDEMIA | P2: DISRUPTS TRANSPORT FUNCTION | Q2: ALTERS GERM CELL DEVELOPMENT, FUNCTION, OR DEATH | R2: AFFECTS ANTIGEN PROCESSING AND PRESENTATION | S2: ALTERS DNA REPAIR OR CAUSES GENOMIC INSTABILITY | T2: ALTERS EFFECTOR FUNCTION OF SPECIFIC CELL TYPES | U2: ALTERS HEMOSTASIS | V2: ALTERS HORMONE DISTRIBUTION OR CIRCULATING HORMONE LEVELS | W2: ALTERS HORMONE METABOLISM OR CLEARANCE | X2: ALTERS IMMUNE CELL SIGNALING | Y2: ALTERS IMMUNE CELL TRAFFICKING | Z2: BREAKS DOWN IMMUNE TOLERANCE | AA2: ACTIVATES STRESS SIGNALING PATHWAYS | AB2: CAUSES CHOLESTASIS | AC2: CAUSES IMMORTALIZATION | AD2: CAUSES LIVER FIBROSIS | AE2: IMPACTS ENDOTHELIAL AND VASCULAR FUNCTION | AF2: IMPAIRS CARDIAC CONTRACTILITY AND RELAXATION | AG2: IMPAIRS REGULATION OF CARDIAC EXCITABILITY | AH2: MODIFIES AUTONOMIC NERVOUS SYSTEM ACTIVITY | AI2: MODIFIES CELLULAR DIFFERENTIATION
A3: Peptide hormone metabolism | B3: 0 | C3: 0 | D3: 0 | E3: 0 | F3: 0 | G3: 0 | H3: 0 | I3: 0 | J3: 0 | K3: 0 | L3: 0 | M3: 0 | N3: 0 | O3: 1 | P3: 0 | Q3: 0 | R3: 0 | S3: 0 | T3: 0 | U3: 0 | V3: 1 | W3: 1 | X3: 0 | Y3: 0 | Z3: 0 | AA3: 0 | AB3: 0 | AC3: 0 | AD3: 0 | AE3: 0 | AF3: 0 | AG3: 0 | AH3: 0 | AI3: 0
A4: Regulation of Insulin-like Growth Factor (IGF) transport and uptake by Insulin-like Growth Factor Binding Proteins (IGFBPs) | B4: 0 | C4: 0 | D4: 0 | E4: 0 | F4: 0 | G4: 0 | H4: 0 | I4: 0 | J4: 0 | K4: 0 | L4: 0 | M4: 0 | N4: 0 | O4: 1 | P4: 0 | Q4: 0 | R4: 0 | S4: 0 | T4: 0 | U4: 0 | V4: 0 | W4: 0 | X4: 0 | Y4: 0 | Z4: 0 | AA4: 0 | AB4: 0 | AC4: 0 | AD4: 0 | AE4: 0 | AF4: 0 | AG4: 0 | AH4: 0 | AI4: 0
A5: Protein folding | B5: 0 | C5: 0 | D5: 0 | E5: 0 | F5: 0 | G5: 0 | H5: 0 | I5: 0 | J5: 0 | K5: 0 | L5: 0 | M5: 0 | N5: 0 | O5: 1 | P5: 0 | Q5: 0 | R5: 0 | S5: 0 | T5: 0 | U5: 0 | V5: 0 | W5: 0 | X5: 0 | Y5: 0 | Z5: 0 | AA5: 0 | AB5: 0 | AC5: 0 | AD5: 0 | AE5: 0 | AF5: 0 | AG5: 0 | AH5: 0 | AI5: 0
A6: Protein repair | B6: 0 | C6: 0 | D6: 1 | E6: 0 | F6: 0 | G6: 0 | H6: 0 | I6: 0 | J6: 0 | K6: 0 | L6: 0 | M6: 0 | N6: 0 | O6: 1 | P6: 0 | Q6: 0 | R6: 0 | S6: 0 | T6: 0 | U6: 0 | V6: 0 | W6: 0 | X6: 0 | Y6: 0 | Z6: 0 | AA6: 0 | AB6: 0 | AC6: 0 | AD6: 0 | AE6: 0 | AF6: 0 | AG6: 0 | AH6: 0 | AI6: 0
A7: Surfactant metabolism | B7: 0 | C7: 0 | D7: 0 | E7: 0 | F7: 0 | G7: 0 | H7: 0 | I7: 0 | J7: 0 | K7: 0 | L7: 0 | M7: 0 | N7: 0 | O7: 1 | P7: 0 | Q7: 0 | R7: 0 | S7: 0 | T7: 0 | U7: 0 | V7: 0 | W7: 0 | X7: 0 | Y7: 0 | Z7: 0 | AA7: 0 | AB7: 0 | AC7: 0 | AD7: 0 | AE7: 0 | AF7: 0 | AG7: 0 | AH7: 0 | AI7: 0
A8: Post-translational protein modification | B8: 0 | C8: 0 | D8: 0 | E8: 0 | F8: 0 | G8: 0 | H8: 0 | I8: 0 | J8: 0 | K8: 0 | L8: 0 | M8: 0 | N8: 0 | O8: 1 | P8: 0 | Q8: 0 | R8: 0 | S8: 0 | T8: 0 | U8: 0 | V8: 0 | W8: 0 | X8: 0 | Y8: 0 | Z8: 0 | AA8: 0 | AB8: 0 | AC8: 0 | AD8: 0 | AE8: 0 | AF8: 0 | AG8: 0 | AH8: 0 | AI8: 0
A9: Translation | B9: 0 | C9: 0 | D9: 0 | E9: 0 | F9: 0 | G9: 0 | H9: 0 | I9: 0 | J9: 0 | K9: 0 | L9: 0 | M9: 0 | N9: 0 | O9: 1 | P9: 0 | Q9: 0 | R9: 0 | S9: 0 | T9: 0 | U9: 0 | V9: 0 | W9: 0 | X9: 0 | Y9: 0 | Z9: 0 | AA9: 0 | AB9: 0 | AC9: 0 | AD9: 0 | AE9: 0 | AF9: 0 | AG9: 0 | AH9: 0 | AI9: 0
A10: Amyloid fiber formation | B10: 0 | C10: 0 | D10: 0 | E10: 0 | F10: 0 | G10: 0 | H10: 0 | I10: 0 | J10: 0 | K10: 0 | L10: 0 | M10: 0 | N10: 0 | O10: 1 | P10: 0 | Q10: 0 | R10: 0 | S10: 0 | T10: 0 | U10: 0 | V10: 0 | W10: 0 | X10: 0 | Y10: 0 | Z10: 0 | AA10: 0 | AB10: 0 | AC10: 0 | AD10: 0 | AE10: 0 | AF10: 0 | AG10: 0 | AH10: 0 | AI10: 0
